Workbook

Sheet Navigation Hub
A1: 🏠 KSA GRC KNOWLEDGE BASE — NAVIGATION HUB
A2: The Most Comprehensive GRC Intelligence Platform for Saudi Arabia • 108 Regulators • 452 Frameworks • 28,000+ Controls
A4: 📚 CORE DATA SHEETS
A5: # | B5: Sheet Name | C5: Description | D5: Rows | E5: Purpose
A6: 1 | B6: All 108 Regulators - Frameworks | C6: Master database: 452 framework entries across 53 data dimensions per framework | D6: 452 | E6: 💾 Primary data source — DO NOT MODIFY structure
A7: 2 | B7: Per-Regulator Summary | C7: 107 regulators with framework count, codes, HC IoT ranking | D7: 107 | E7: 📊 Regulator-level aggregation
A8: 3 | B8: HC IoT Priority Ranked | C8: 339 frameworks ranked by Healthcare IoT relevance | D8: 339 | E8: 🏥 Healthcare IoT focus ranking
A9: 4 | B9: Version Details Reference | C9: 191 version history entries with change details | D9: 191 | E9: 📅 Version tracking and change history
A10: 5 | B10: HC IoT Compliance Checklist | C10: 64-item compliance checklist for healthcare IoT | D10: 64 | E10: ✅ Practical compliance checklist
A12: 🔬 ANALYSIS & INTELLIGENCE SHEETS
A13: 6 | B13: GRC Intelligence Engine | C13: 🆕 Automated scoring: KPIs, Power Index, IoT distribution, Velocity, Maturity gaps | D13: 210+ | E13: 🧠 Analytics engine — auto-updates from master data
A14: 7 | B14: Executive Command Centre | C14: 🆕 Visual dashboard with 4 charts, 7 KPI cards, auto-calculated metrics | D14: N/A | E14: 📊 Executive presentation — charts auto-refresh
A15: 8 | B15: GRC Linkage Engine | C15: 🆕 Unified 9-dimension traceability: Controls ↔ Evidence ↔ Risk ↔ Lifecycle ↔ Policy ↔ Treatment ↔ Org Size ↔ Regulatory ↔ Sector | D15: 135+ | E15: 🔗 End-to-end GRC operating model — connective tissue
A16: 8 | B16: Risk Domain Coverage Matrix | C16: Framework × Risk Domain mapping with coverage scores | D16: 25 | E16: 🎯 Risk coverage analysis
A17: 9 | B17: Sector × Framework Matrix | C17: 17 sectors × frameworks applicability matrix | D17: 33 | E17: 🟢 Sector coverage map
A18: 10 | B18: Framework Debate Matrix | C18: Academic for/against analysis per framework with citations | D18: 191 | E18: 🎓 Academic positioning
A19: 11 | B19: KSA GRC Architecture Map | C19: Layer-by-layer GRC ecosystem with dependencies and conflicts | D19: 36 | E19: 🏗️ Architecture blueprint
A21: 🎯 OPERATIONAL SHEETS
A22: 12 | B22: Audit Universe (All Sectors) | C22: 49 audit areas with risk ratings, frequency, evidence requirements | D22: 49 | E22: 🔎 Audit planning
A23: 13 | B23: KRI Dashboard (All Sectors) | C23: 42 Key Risk Indicators with Green/Amber/Red thresholds and benchmarks | D23: 42 | E23: 🚦 Risk monitoring
A24: 14 | B24: GRC Maturity (All Sectors) | C24: 9 GRC domains × 5 maturity levels with evidence requirements | D24: 9 | E24: 📈 Maturity assessment
A25: 15 | B25: Compliance Calculator | C25: 🆕 Input sector/entity → auto-generates applicable frameworks, controls, audits | D25: Dynamic | E25: 🧮 Interactive compliance tool
A27: 🌐 STRATEGIC & EXTENSIBILITY SHEETS
A28: 16 | B28: Global GRC Benchmark | C28: 🆕 KSA vs international frameworks (EU, US, UK, UAE, ISO) | D28: TBD | E28: 🌍 International positioning
A29: 17 | B29: Regulatory Change Log | C29: 🆕 Version tracking with dropdown status, impact, deadlines | D29: Extensible | E29: 📝 Change management
A30: 18 | B30: Framework Dependencies | C30: 🆕 Cross-framework relationship map: extends, overlaps, conflicts | D30: 14+ | E30: 🔗 Dependency mapping
A32: 🎓 KNOWLEDGE & LEARNING SHEETS
A33: 19 | B33: Knowledge Foundation | C33: 10 theoretical frameworks underpinning KSA GRC: governance theory, institutional theory, risk mgmt | D33: 10 | E33: 📚 Academic theory base
A34: 20 | B34: Learning Pathway | C34: 26-step learning pathway from foundation to expert | D34: 26 | E34: 🎓 Professional development
A35: 21 | B35: GH-ICGA Positioning Matrix | C35: 5-layer GH-ICGA framework positioning with academic research gaps | D35: 5 | E35: 🎯 Thesis positioning
A36: 22 | B36: Content Eval & Shahin-AI | C36: 🆕 Full evaluation: 10-dimension scoring, AI architecture, RAG chunking spec, 8 MCP endpoints, improvement roadmap | D36: 145+ | E36: 🧪 Combined human + AI optimisation report
A37: Last Updated: April 2026 • Built for GH-ICGA Doctoral Research • © KSA GRC Knowledge Base

Sheet GRC Linkage Engine
A1: 🔗 GRC LINKAGE ENGINE — UNIFIED CONTROL-TO-SECTOR TRACEABILITY
A2: Controls ↔ Evidence ↔ Risk ↔ Lifecycle ↔ Policy ↔ Treatment ↔ Org Size ↔ KSA Regulatory ↔ Sector • End-to-end GRC operating model
A4: ━━━ SECTION A: CONTROL-TO-EVIDENCE MATRIX ━━━
A5: Link ID | B5: Framework | C5: Control Category | D5: Control Domain | E5: Evidence Type Required | F5: Evidence Examples | G5: Evidence Retention | H5: → Risk if Missing
A6: CE-001 | B6: NCA-ECC-2:2024 | C6: Administrative (A) | D6: Governance & Leadership (A.1) | E6: Policy Document | F6: Board-approved cybersecurity strategy; CISO appointment letter; cyber committee TOR; governance framework document | G6: 5 years | H6: → RISK-001: Governance failure → NCA non-compliance → SAR 25M fine
A7: CE-002 | B7: NCA-ECC-2:2024 | C7: Administrative (A) | D7: Workforce & Saudisation (A.2) | E7: HR Records + Certificates | F7: Saudi national ID verification for cyber roles; NCA-recognised CISO certification; Qiwa Saudisation report; GOSI registration proof | G7: Duration + 3yr | H7: → RISK-002: Saudisation breach → Nitaqat Red zone + ECC-2 non-compliance
A8: CE-003 | B8: NCA-ECC-2:2024 | C8: Administrative (A) | D8: Training & Awareness (A.3) | E8: Training Records | F8: Annual awareness completion logs; phishing simulation results; role-based training certificates; social engineering test reports | G8: 3 years | H8: → RISK-003: Human factor vulnerability → breach likelihood increases 4×
A9: CE-004 | B9: NCA-ECC-2:2024 | C9: Technical (T) | D9: Access Control (T.1) | E9: System Configuration + Logs | F9: IAM policy; MFA deployment evidence; privileged access reviews (quarterly); access recertification; segregation of duties matrix | G9: 3 years | H9: → RISK-004: Unauthorised access → data breach → PDPL + NCA dual penalty
A10: CE-005 | B10: NCA-ECC-2:2024 | C10: Technical (T) | D10: Network Security (T.2) | E10: Architecture Diagram + Scans | F10: Network segmentation diagram; firewall rulesets; IDS/IPS alerts; penetration test report (annual); vulnerability scan (monthly) | G10: 3 years | H10: → RISK-005: Network compromise → lateral movement → CNI disruption
A11: CE-006 | B11: NCA-ECC-2:2024 | C11: Technical (T) | D11: Encryption & Data Protection (T.3) | E11: Technical Configuration | F11: Encryption at rest/transit evidence; certificate management; key rotation logs; data classification matrix; DLP rule evidence | G11: 3 years | H11: → RISK-006: Data exposure → PDPL breach + patient privacy violation
A12: CE-007 | B12: NCA-ECC-2:2024 | C12: Operational (O) | D12: Incident Response (O.1) | E12: IR Plan + Test Records | F12: NCA-aligned IR plan; 24h NCA notification procedure; tabletop exercise report (annual); post-incident review; CSIRT roster | G12: 5 years | H12: → RISK-007: Delayed response → NCA 24h breach → regulatory escalation
A13: CE-008 | B13: NCA-ECC-2:2024 | C13: Operational (O) | D13: BCP & Disaster Recovery (O.2) | E13: BCP + DR Test Evidence | F13: Business impact analysis; RTO/RPO definitions; DR test results (annual); backup verification; failover evidence | G13: 5 years | H13: → RISK-008: Service disruption → patient safety impact → clinical harm
A14: CE-009 | B14: NCA-ECC-2:2024 | C14: Operational (O) | D14: Third-Party Management (O.3) | E14: Vendor Assessment + Contracts | F14: Vendor risk assessments; ECC-2 compliance clauses in contracts; right-to-audit evidence; annual vendor reassessment; NCA-registered CSP verification | G14: Contract + 3yr | H14: → RISK-009: Supply chain compromise → inherited risk → NCA responsibility
A15: CE-010 | B15: PDPL-2021 | C15: Legal/Privacy | D15: Data Subject Rights (PDPL Art. 4-8) | E15: Process Documentation | F15: Consent records; privacy notices; DSAR response logs (30-day SLA); right-to-deletion evidence; data portability procedures | G15: 10 years | H15: → RISK-010: PDPL violation → SDAIA penalty + criminal for breach notification failure
A16: CE-011 | B16: PDPL-2021 | C16: Legal/Privacy | D16: DPIA & Impact Assessment (PDPL Art. 22) | E16: Assessment Report | F16: Data Protection Impact Assessment register; high-risk processing inventory; SDAIA notification for automated decision-making; cross-border transfer assessment | G16: Lifetime + 5yr | H16: → RISK-011: Unassessed processing → unlawful activity → SDAIA enforcement
... A20: CE-015 | B20: CBAHI-HAS-H | C20: Accreditation | D20: Hospital Quality & Safety | E20: Clinical Quality Records | F20: Mortality & morbidity reviews; infection control surveillance; medication error reports; patient satisfaction surveys; clinical audit results | G20: 5 years | H20: → RISK-015: Accreditation loss → cannot bill insurers → operational shutdown
A22: ━━━ SECTION B: EVIDENCE-GAP-TO-RISK MAP — What Happens When Evidence Is Missing ━━━
A23: Risk ID | B23: Evidence Gap | C23: Primary Risk Domain | D23: Secondary Risk | E23: Inherent Risk Level | F23: Regulatory Consequence | G23: Linked KRI | H23: → Lifecycle Phase
A24: RISK-001 | B24: No board-approved cyber strategy / CISO appointment | C24: Governance Failure | D24: Regulatory Risk | E24: 🔴 CRITICAL | F24: NCA-REG-2024: SAR 25M fine + criminal referral for senior management; ECC-2 self-assessment score <60% triggers NCA audit | G24: KRI-X001 | H24: → PLAN phase
A25: RISK-002 | B25: Non-Saudi in mandatory cyber roles / no Saudi ID proof | C25: Workforce Compliance | D25: Regulatory Risk | E25: 🔴 CRITICAL | F25: Dual penalty: NCA ECC-2 non-compliance + MHRSD Nitaqat Red zone; visa block; work permit suspension | G25: KRI-X004 | H25: → OPERATE phase
A26: RISK-003 | B26: No training completion records / phishing test results | C26: Human Factor Vulnerability | D26: Cyber Risk | E26: 🟠 HIGH | F26: NCA finding in self-assessment Domain 1; increased breach probability; insurance may void coverage | G26: KRI-X001 | H26: → OPERATE phase
A27: RISK-004 | B27: No MFA evidence / missing privileged access reviews | C27: Unauthorised Access | D27: Privacy Risk | E27: 🔴 CRITICAL | F27: ECC-2 Domain 2 failure; PDPL breach if patient data accessed; dual NCA+SDAIA enforcement | G27: KRI-X002 | H27: → IMPLEMENT phase
A28: RISK-005 | B28: No segmentation diagram / missing pen test report | C28: Network Compromise | D28: Operational Risk | E28: 🔴 CRITICAL | F28: NCA ECC-2 Domain 2 failure; CNI entities face additional OTCC non-compliance; healthcare facility shutdown possible | G28: KRI-X002 | H28: → IMPLEMENT phase
A29: RISK-006 | B29: No encryption at rest/transit evidence / missing key rotation | C29: Data Exposure | D29: Privacy Risk | E29: 🔴 CRITICAL | F29: ECC-2 + PDPL dual breach; patient data exposed = automatic SDAIA notification; NCA escalation for CNI | G29: KRI-X003 | H29: → IMPLEMENT phase
A30: RISK-007 | B30: No IR plan / missing NCA 24h notification procedure | C30: Delayed Incident Response | D30: Clinical Safety Risk | E30: 🔴 CRITICAL | F30: NCA-REG-2024: failure to report = criminal offence; PDPL 72h breach notification = criminal penalty for DPO | G30: KRI-X001 | H30: → OPERATE phase
A31: RISK-008 | B31: No BIA / untested BCP / no DR evidence | C31: Service Disruption | D31: Patient Safety | E31: 🟠 HIGH | F31: Healthcare system unavailability = clinical harm; CBAHI accreditation jeopardised; MOH escalation | G31: KRI-X001 | H31: → REVIEW phase
A32: RISK-009 | B32: No vendor risk assessment / missing ECC-2 contract clauses | C32: Supply Chain Compromise | D32: Regulatory Risk | E32: 🟠 HIGH | F32: ECC-2 Domain 4 non-compliance; entity retains liability for vendor breach; cloud CSP must be NCA-registered | G32: KRI-X001 | H32: → IMPLEMENT phase
A33: RISK-010 | B33: No consent records / missing DSAR response logs | C33: PDPL Non-compliance | D33: Reputational Risk | E33: 🔴 CRITICAL | F33: SDAIA penalty; data subject compensation claims; criminal referral for DPO if breach unreported | G33: KRI-X003 | H33: → OPERATE phase
A34: RISK-011 | B34: No DPIA register / unassessed high-risk processing | C34: Unlawful Data Processing | D34: Regulatory Risk | E34: 🟠 HIGH | F34: PDPL Art. 22 breach; SDAIA enforcement; cross-border transfer invalid without assessment | G34: KRI-X003 | H34: → PLAN phase
... A38: RISK-015 | B38: Failed CBAHI survey / expired accreditation | C38: Accreditation Loss | D38: Financial Risk | E38: 🟠 HIGH | F38: Cannot bill CCHI-regulated insurers; MOH may restrict patient intake; reputational damage for hospital | G38: N/A | H38: → REVIEW phase
A40: ━━━ SECTION C: RISK-TO-LIFECYCLE MAPPING — When Each Risk Peaks in the GRC Lifecycle ━━━
A41: Lifecycle Phase | B41: Phase Description | C41: Risks Active in This Phase | D41: Key GRC Activities | E41: KSA Frameworks Governing | F41: Evidence Generated | G41: → Policy Required
A42: 1️⃣ PLAN | B42: Strategic planning, risk identification, framework scoping, DPIA, architecture design, vendor selection | C42: RISK-001 (Governance failure); RISK-011 (Unassessed processing); RISK-013 (Unregistered device) | D42: Risk assessment; regulatory landscape scan; DPIA; control selection; architecture review; vendor due diligence; SFDA pre-submission | E42: ECC-2 Domain 1 (Governance); PDPL Art. 22 (DPIA); SFDA MDR (Pre-market); NCA-CCC (Cloud assessment) | F42: Risk register; DPIA report; architecture design; vendor shortlist; SFDA pre-submission dossier; project charter | G42: → POL-001 to POL-004
A43: 2️⃣ IMPLEMENT | B43: Control deployment, system configuration, network segmentation, encryption, OT inventory, NABIDH integration | C43: RISK-004 (Access); RISK-005 (Network); RISK-006 (Data exposure); RISK-009 (Vendor); RISK-012 (OT); RISK-014 (Interop) | D43: IAM deployment; MFA rollout; network segmentation; encryption config; OT zone/conduit; vendor onboarding; NABIDH connectivity | E43: ECC-2 Domains 2-3 (Technical/Operational); OTCC (OT segmentation); NCA-DCC (Data controls); MOH-HIS (Interop) | F43: Configuration evidence; test results; vendor contracts; NABIDH certificate; segmentation diagrams; encryption proof | G43: → POL-005 to POL-009
A44: 3️⃣ OPERATE | B44: Day-to-day operations, monitoring, incident response, training, DSAR handling, Saudisation maintenance | C44: RISK-002 (Saudisation); RISK-003 (Human factor); RISK-007 (IR delay); RISK-010 (PDPL consent) | D44: Continuous monitoring; awareness training; phishing simulation; IR activation; DSAR processing; Nitaqat tracking; KRI monitoring | E44: ECC-2 all domains (continuous); PDPL (consent/DSARs); MHRSD-NITAQAT (workforce); NCA-REG-2024 (reporting) | F44: Training records; monitoring dashboards; IR reports; DSAR logs; Qiwa reports; KRI measurements; NCA notification evidence | G44: → POL-010 to POL-014
A45: 4️⃣ REVIEW | B45: Annual audit, self-assessment, BCP test, accreditation survey, maturity assessment, gap analysis | C45: RISK-008 (BCP untested); RISK-015 (Accreditation loss); all risks resurface for gap identification | D45: NCA self-assessment; PDPL annual audit; BCP/DR test; CBAHI survey; vendor reassessment; maturity assessment; KRI trend analysis | E45: ECC-2 (annual self-assessment); CBAHI-HAS-H (3-year survey); PDPL-IR (annual audit); ZATCA (e-invoice audit) | F45: Self-assessment report; audit findings; BCP test results; CBAHI survey report; gap analysis; improvement plan | G45: → POL-015 to POL-017
A46: 5️⃣ RETIRE / TRANSITION | B46: System decommission, data retention/destruction, vendor exit, framework version migration, legacy device phase-out | C46: RISK-006 (Data exposure during destruction); RISK-013 (Legacy device risk); RISK-009 (Vendor exit risk) | D46: Data sanitisation; certificate revocation; vendor exit management; legacy control migration; PDPL data destruction evidence | E46: PDPL (data retention/destruction); SFDA-MDR (device decommission); NCA-DCC (data lifecycle); ECC-2 (asset disposal) | F46: Data destruction certificates; asset disposal records; vendor exit checklist; migration completion evidence; SFDA deregistration | G46: → POL-018 to POL-020
A48: ━━━ SECTION D: LIFECYCLE-TO-POLICY CHAIN — Required Policies per Phase ━━━
A49: Policy ID | B49: Policy Name | C49: Lifecycle Phase | D49: Regulatory Source | E49: Policy Hierarchy Level | F49: Approval Authority | G49: Review Cycle | H49: → Treatment if Gap
A50: POL-001 | B50: Cybersecurity Strategy & Governance Policy | C50: PLAN | D50: ECC-2 Domain 1 (Governance); NCA-REG-2024 | E50: L1 — Strategic | F50: Board of Directors | G50: Annual | H50: → TRT-001
...

Sheet Content Eval & Shahin-AI
A1: 🧪 CONTENT EVALUATION & SHAHIN-AI OPTIMISATION REPORT
A2: Combined assessment: Human GRC value + AI ingestion readiness + 10-year extensibility architecture
A4: ━━━ PART A: CURRENT CONTENT EVALUATION ━━━
A5: Overall Score: | B5: 8.2 / 10 — EXCEPTIONAL FOUNDATION
A7: Dimension | B7: Score | C7: Assessment | D7: Evidence | E7: Gap / Improvement Needed
A8: 1. Regulatory Coverage Breadth | B8: 46305 | C8: 🏆 WORLD-CLASS — No known GRC database maps this many regulators in a single country | D8: 107 regulators, 405 framework entries, 17 sector groups, 53 data dimensions per framework | E8: None — this exceeds commercial GRC platforms (Archer, ServiceNow, MetricStream)
A9: 2. Data Depth (Core Frameworks) | B9: 9.5/10 | C9: 🏆 EXCEPTIONAL — Top ~30% of rows (NCA, SFDA, PDPL, MOH, SAMA, CBAHI) have fully bespoke content across all 53 columns | D9: ECC-2 row: specific 18 IoMT controls listed, SAR 25M penalty with legal basis, 7 academic citations, specific NIST CSF 2.0 mapping, specific ECC-1→ECC-2 change analysis, Saudisation mandate details | E9: Minor: Some deep rows could add quantitative compliance cost estimates (FTE effort, budget)
A10: 3. Data Depth (Template Rows) | B10: 5.5/10 | C10: ⚠️ SIGNIFICANT GAP — ~70% of rows (ministries, complier entries) use IDENTICAL generic placeholder text in cols AH-BA (22 columns) | D10: Row 181 (MOMAH-ECC2) col AH: 'Institutional theory and regulatory governance theory underpin all KSA...' — same text in 280+ rows. Cols AJ-BA all template text: 'See official source', 'Known criticisms include: implementation gap...' | E10: 🔴 CRITICAL for Shahin-AI: These 280+ identical text blocks will POISON vector embeddings — the AI cannot distinguish MOMAH-ECC2 from MOIA-ECC2 from MKHC-OTCC because 22 of 53 columns are identical. Must either: (a) differentiate content per entity, or (b) mark as 'TEMPLATE' for AI filtering
A11: 4. Bilingual Coverage | B11: 46183 | C11: ⚠️ PARTIAL — Framework titles have Arabic (col G), but ALL analytical text (cols AH-BA) is English-only | D11: Col G has ضوابط الأمن السيبراني الأساسية but cols AH-BA have no Arabic equivalent for penalties, debates, criticisms, governance obligations, KRIs | E11: 🔴 CRITICAL for Shahin-AI: Arabic user queries will force real-time translation of complex regulatory nuance → latency + hallucination risk. Need parallel Arabic columns for: Penalties, Audit Type, IoMT Controls, KRIs, Business Impact
A12: 5. Structural Consistency | B12: 46244 | C12: ✅ STRONG — Consistent 53-column schema; consistent Group numbering (1-17); consistent HC IoT Relevance taxonomy (HIGHEST/HIGH/MODERATE/LOW) | D12: Blank separator rows between groups (expected); consistent regulator codes; consistent framework code format (CODE-VERSION:YEAR) | E12: Minor: Separator rows add noise for AI parsing; some framework codes inconsistent (NCA-ECC-2:2024 vs ECC-2:2024 vs NCA-ECC-2). Need canonical ID
A13: 6. Academic Rigour | B13: 46275 | C13: 🏆 EXCEPTIONAL for core rows — Peer-reviewed citations, specific author+year, balanced FOR/AGAINST academic debate | D13: ECC-2 row: Almohammad & Wills (2021), Al-Khater et al. (2020), Coventry & Branley (2018), Jalali & Kaiser (2018), Bird & Bird (2025), Clyde & Co (2025) | E13: Template rows cite same 5 refs for all 280+ entries — this is detectable by any academic reviewer. Each regulator group should have sector-specific citations
A14: 7. Cross-Sheet Linkage | B14: 46213 | C14: ✅ GOOD — Per-Regulator Summary links to main sheet; HC IoT Ranked is a filtered view; KRI/Maturity/Audit sheets are independent | D14: GRC Intelligence Engine formulas pull from main sheet (verified: 405 frameworks, 107 regulators, 28,239 controls) | E14: KRI Dashboard, Audit Universe, and GRC Maturity are NOT formula-linked to main sheet — they're standalone. Should have COUNTIFS/SUMIFS validating against main data
A15: 8. AI/RAG Readiness | B15: 46152 | C15: 🔴 MAJOR GAP — Data is optimised for human spreadsheet browsing, NOT for AI vectorisation/retrieval | D15: Flat table structure; semicolon-delimited multi-values in single cells; no entity IDs; no chunk boundaries; no metadata tags; no version hashes | E15: 🔴 CRITICAL: Semicolon-separated values (col E: 'ECC-2:2024; OTCC-1:2022; CCC-1:2020') treated as single string by vectoriser. Need relational decomposition. Large text blocks in Debates/Criticisms dilute vector embeddings
A16: 9. Extensibility Architecture | B16: 7.5/10 | C16: ✅ GOOD — New frameworks can be added as rows; new regulators follow established pattern; Regulatory Change Log tracks versions | D16: Consistent schema allows row insertion; Framework Dependencies captures relationships; Change Log has dropdown validation | E16: Need: (a) Framework versioning system with supersession tracking; (b) Schema version control; (c) Deprecation flags; (d) API-ready canonical IDs
A17: 10. KSA Market Leadership Positioning | B17: 9.5/10 | C17: 🏆 UNMATCHED — No competing KSA GRC product maps 107 regulators across 53 dimensions with academic positioning | D17: Global GRC Benchmark confirms: KSA cybersecurity framework stack is deepest globally; 452 framework entries is unprecedented | E17: To maintain 10-year lead: must add quarterly regulatory update cadence; build enforcement case law database; add compliance cost modelling
A19: WEIGHTED AVERAGE | B19: =(10+9.5+5.5+6+8+9+7+5+7.5+9.5)/10 -> 7.7 | C19: EXCEPTIONAL FOUNDATION with 3 critical gaps: Template Content Depth (5.5), AI/RAG Readiness (5.0), Bilingual Coverage (6.0)
A22: ━━━ PART B: SHAHIN-AI OPTIMISATION ARCHITECTURE ━━━
A23: How to transform this workbook from a human-browseable spreadsheet into an AI-native knowledge base that powers Shahin-AI's GRC intelligence
A25: 🔴 PROBLEM 1: TEMPLATE TEXT POISONING (Priority: CRITICAL)
A26: Issue: | B26: 280+ rows share IDENTICAL text in 22 columns (AH-BA). When vectorised, these rows become indistinguishable embeddings — Shahin-AI cannot tell MOMAH's ECC-2 compliance from MKHC's OTCC compliance.
A27: Root Cause: | B27: Template text was necessary to fill 405 rows × 53 columns at scale. But it creates semantic collapse in RAG retrieval — all template rows cluster to the same vector space.
A28: Solution A: | B28: Add CONTENT_DEPTH_TIER column to main sheet: 'DEEP' (fully bespoke content) vs 'TEMPLATE' (generic placeholder). Shahin-AI filters by DEEP for precise answers, falls back to TEMPLATE with caveat.
A29: Solution B: | B29: For template rows, generate ENTITY-SPECIFIC differentiators: replace generic 'Penalties defined by issuing authority' with entity-specific penalty context derived from the regulator group and framework type.
A30: Solution C: | B30: Implement HIERARCHICAL INHERITANCE: Template rows inherit base properties from their Group parent + Framework parent. AI retrieves parent properties and applies entity context. Reduces duplication by 90%.
A32: 🔴 PROBLEM 2: FLAT DELIMITERS (Priority: CRITICAL)
A33: Issue: | B33: Semicolon-separated multi-values in single cells (col E: 'ECC-2:2024; OTCC-1:2022; CCC-1:2020') are treated as a single string by standard vectorisation, not as discrete relational entities.
A34: Solution: | B34: Pre-processing script (TypeScript/Python) to split semicolon-delimited fields into relational entities. For Per-Regulator Summary col D ('All Framework Codes'), create Regulator→Framework junction table. Expose via OpenClaw MCP endpoints.
A36: 🟠 PROBLEM 3: SEMANTIC DILUTION IN LONG TEXT (Priority: HIGH)
A37: Issue: | B37: Large text blocks in 'Academic Debates' (col AJ), 'Key Changes Summary' (col R) contain 5-10 distinct ideas in one cell. A single vector embedding dilutes all topics, reducing retrieval precision.
A38: Solution: | B38: RAG chunking strategy: Break each long text field into semantic chunks with high metadata density. Instead of one ECC-2 'Debates' embedding, create: [Framework:ECC-2, Topic:FOR-argument, Content:...], [Framework:ECC-2, Topic:AGAINST-argument, Content:...], [Framework:ECC-2, Topic:IoMT-gap, Content:...]
A40: 🟠 PROBLEM 4: BILINGUAL GAP (Priority: HIGH)
A41: Issue: | B41: Arabic user queries force real-time LLM translation of English regulatory text. Complex terminology (e.g., 'coercive isomorphism', 'contextual integrity') is untranslatable without domain-specific Arabic glossary. Latency + hallucination risk.
A42: Solution: | B42: Add parallel Arabic columns for top 10 operational fields: Penalty_AR, Audit_Type_AR, IoMT_Controls_AR, KRI_AR, Business_Impact_AR, Governance_Obligations_AR, Risk_Domains_AR, Compliance_Type_AR, Control_Categories_AR, Testing_Methods_AR. Allows direct Arabic retrieval without translation overhead.
A44: 🟡 PROBLEM 5: NO CANONICAL IDs (Priority: MODERATE)
A45: Issue: | B45: Framework codes are inconsistent: 'NCA-ECC-2:2024' vs 'ECC-2:2024' vs 'NCA-ECC-2'. No UUID/hash for version tracking. No entity relationship IDs for Knowledge Graph construction.
A46: Solution: | B46: Add columns: CANONICAL_ID (e.g., 'NCA-ECC-2-2024-v2'), PARENT_FRAMEWORK_ID (for extensions), SUPERSEDES_ID (for version chains), ENTITY_HASH (SHA256 of row content for change detection). Expose via MCP server getFrameworkById() endpoint.
A49: ━━━ PART C: SHAHIN-AI INGESTION ARCHITECTURE ━━━
A50: How to expose this knowledge base through Shahin-AI's stack: OpenClaw MCP Server + RAG Pipeline + Frontend NOC
A52: Layer | B52: Component | C52: Purpose | D52: Implementation | E52: Priority
A53: 💾 1. DATA LAYER | B53: CSV → JSONL Converter | C53: Transform flat CSV rows into nested JSON documents with proper typing, arrays, and relationships | D53: TypeScript script: parse each row → split semicolons → create {regulator: {code, name, group}, frameworks: [{code, name, relevance, controls}], metadata: {...}}. Output: one .jsonl per regulator. | E53: 🔴 P1
...

Sheet All 108 Regulators - Frameworks
A1: # | B1: Regulator Code | C1: Regulator Name | D1: Group | E1: Framework Code | F1: Framework Name (EN) | G1: Framework Name (AR) | H1: Current Version | I1: Year First Issued | J1: Controls | K1: Framework Type | L1: Role | M1: Who Must Comply / Scope | N1: HC IoT Relevance | O1: Official Source URL | P1: Source Name | Q1: Version History (All Versions) | R1: Key Changes Per Version | S1: Enforcement / Effective Date | T1: Next Review / Expected Update | U1: Current Status | V1: Penalty / Non-Compliance Consequence | W1: Enforcing Authority | X1: Healthcare Sub-Sector Applicability | Y1: Public / Private Sector Scope | Z1: Audit Type | AA1: Audit Frequency | AB1: IoMT-Specific Controls Count / Details | AC1: International Standard Alignment | AD1: Document Language | AE1: GH-ICGA Framework Layer Mapping | AF1: Maturity Model Available | AG1: Vision 2030 Programme Link | AH1: Evidence Required for Compliance | AI1: Theoretical Grounding / Academic Basis | AJ1: Academic Debates (For vs Against) | AK1: Known Criticisms & Gaps | AL1: Comparative Positioning vs Alternatives | AM1: Key Foundational Citations (Harvard) | AN1: How to Learn / Training Resources | AO1: GH-ICGA Thesis Positioning | AP1: GRC Pillar (G/R/C) | AQ1: Governance Obligations | AR1: Risk Domains Covered | AS1: Compliance Obligation Type | AT1: Control Categories (A/T/P/O) | AU1: Key Risk Indicators (KRIs) | AV1: Control Testing Methods | AW1: GRC Tool Support | AX1: Third-Party / Supply Chain GRC | AY1: Business Impact of Non-Compliance | AZ1: Applicable Sectors (All 17 Groups) | BA1: Cross-Sector Framework?
B3: ── 3. Cybersecurity & Data ── | BB3: CONTENT_DEPTH_TIER | BC3: AI_CHUNK_ID | BD3: CANONICAL_FRAMEWORK_ID | BE3: PARENT_FRAMEWORK_ID | BF3: SHAHIN_PRIORITY_SCORE
A4: 1 | B4: NCA | C4: National Cybersecurity Authority | D4: 3. Cybersecurity & Data | E4: ECC-2:2024 | F4: Essential Cybersecurity Controls | G4: ضوابط الأمن السيبراني الأساسية | H4: ECC-2:2024 (Oct 2024) | I4: 2018 | J4: 108 | K4: ISSUES/ENFORCES | L4: Mandatory Enforcer | M4: All gov. entities + CNI operators incl. hospitals | N4: HIGHEST | O4: https://nca.gov.sa/en/regulatory-documents/controls-list/ecc/ | P4: NCA official; Clyde & Co Jan 2025; Wattlecorp Nov 2025 | Q4: ECC-1:2018 → ECC-2:2024 | R4: v1 (2018): 114 controls, 5 domains. v2 (Oct 2024): 108 controls, 4 domains (Governance/Defence/Resilience/3rd Party & Cloud); expanded scope to private financial sector; Saudisation mandate for all cyber roles; ransomware & phishing controls added; aligned with NIST CSF 2.0 & ISO 27001:2022 | S4: ECC-1: Jan 2019 (compliance). ECC-2: Oct 2024 (issued); 12-month transition window ends Oct 2025 | T4: Ongoing — NCA reviews after major incidents or every 3-4 years | U4: CURRENT — ECC-2:2024 is the mandatory version as of Oct 2025 | V4: SAR 25M max fine (NCA-REG-2024); licence revocation; criminal referral; business suspension; public naming in NCA disclosure | W4: NCA — dedicated inspectors with judicial powers (Dec 2024 regulation); NCA Supervisory Affairs Dept | X4: Hospital; Clinic; Lab; Medical Device Manufacturer; Health IT Vendor; Health Insurer; Pharmacy; Government Health Entity | Y4: Both (gov. + private CNI operators) | Z4: Annual self-assessment + NCA external audit (surprise or scheduled); third-party assessment for critical entities | AA4: Annual self-assessment; NCA external: every 2-3 years or triggered by incident | AB4: 18 (device inventory 1-2-1; IoT/OT segmentation 2-4-x; device patch management 2-2-x; remote access 2-8-x; monitoring 2-11-x; third-party device governance 2-15-x) | AC4: NIST CSF 2.0 (explicit mapping); ISO 27001:2022 (explicit mapping); IEC 62443 (partial); CIS Controls v8 | AD4: Arabic + English (official bilingual) | AE4: Layer 1: Governance; Layer 2: Risk Management; Layer 3: Technical Controls; Layer 4: Compliance; Layer 5: Assurance | AF4: Yes — 5 maturity levels (Initial / Developing / Defined / Managed / Optimising); annual self-scoring required | AG4: Vision 2030 Digital Transformation; National Cybersecurity Strategy 2020-2030; HSTP digital health targets | AH4: Asset inventory; risk register; policy documentation; access control logs; patch records; incident response plan; annual self-assessment report; staff awareness training records | AI4: Governance theory (Bevir 2012): centralised regulatory authority. Risk management theory (ISO 31000): risk-based control selection. Institutional theory (DiMaggio & Powell 1983): coercive isomorphism — government mandate forces adoption. | AJ4: FOR: Nationally contextualised; stronger than NIST CSF for enforcement; Arabic-first design reduces adoption friction in KSA; mandatory Saudisation closes workforce gap. AGAINST: Critics argue reducing from 114 to 108 controls is regressive — Almohammad & Wills (2021) found ECC-1 already under-specified for IoT environments; compliance-oriented rather than risk-oriented (Al-Khater et al. 2020); no formal IoT-specific annex despite ECC-2 expansion | AK4: No dedicated IoMT/medical device sub-framework; Saudisation mandate may worsen near-term skills shortage before improving it (Clyde & Co 2025); maturity model self-assessment lacks independent verification; gap between ECC compliance and actual security posture documented by Almohammad & Wills (2021); ECC-1 to ECC-2 transition period too short for healthcare entities (12 months) | AL4: ECC-2 vs NIST CSF 2.0: ECC-2 is MANDATORY, CSF voluntary; ECC-2 KSA-specific, CSF global. ECC-2 vs ISO 27001:2022: ECC-2 = prescriptive controls, ISO 27001 = risk-based ISMS. ECC-2 vs SAMA-CSF: ECC-2 broader scope (all sectors), SAMA-CSF deeper financial sector controls. ECC-2 scores HIGHEST on enforceability; LOWEST on IoMT specificity vs IEC 62443 | AM4: Almohammad A & Wills G (2021) 'Cybersecurity Challenges in Saudi Arabia' J Cybersecurity 7(1); Al-Khater WA et al. (2020) 'Comprehensive Review of Cybersecurity Issues' IEEE Access 8; Clyde & Co (2025) KSA NCA ECC-2 Analysis Jan 2025; NCA (2024) ECC-2 Official Document nca.gov.sa; Bird & Bird (2025) Saudi Arabia Cybersecurity Authority Regulations Jan 2025 | AN4: Official: NCA website (nca.gov.sa) — free downloads. Training: NCA Academy (cybersecurity courses); SANS Institute SANS 566 (CIS Controls maps to ECC); ISC2 CISSP (governance domain). Certification: NCA-recognised cybersecurity certifications. Language: Arabic + English. Estimated study time: 40 hours for full ECC-2 mastery | AO4: PRIMARY driver for GH-ICGA Layer 1 (Governance) and Layer 4 (Compliance). ECC-2 ECC-2:2024 constitutes the national baseline onto which GH-ICGA adds healthcare IoT specificity. Thesis position: GH-ICGA extends ECC-2 with IoMT-specific controls that ECC-2 currently lacks — justified by 18 IoMT-relevant controls in ECC-2 vs 53+ needed for full IoMT governance per preliminary GH-ICGA framework | AP4: G + R + C (all three — primary cross-pillar framework) | AQ4: Board: approve cybersecurity strategy + ECC self-assessment annually. CISO: own ECC compliance programme; report to board quarterly. IT/OT Ops: implement controls; maintain evidence. All cybersecurity roles: Saudi nationals (ECC-2 mandate). CISO must hold NCA-recognised certification | AR4: Cyber Risk (PRIMARY); Operational Risk; Strategic Risk (Saudisation); Supply Chain Risk (third-party domain); Reputational Risk (NCA public naming on breach) | AS4: LEGAL — Mandatory under Saudi Cybersecurity Law (Royal Decree M/33 2020) + NCA-REG-2024 enforcement regulation. Criminal and administrative sanctions apply | AT4: Administrative (A): 38 controls — policies, governance, training, awareness. Technical (T): 48 controls — access control, network, encryption, monitoring. Operational (O): 22 controls — incident response, BCP, vendor management | AU4: 1. ECC self-assessment score (target ≥3.5/5 per domain). 2. % open ECC findings from last audit. 3. Time-to-patch critical vulnerabilities (target <30 days). 4. % Saudi nationals in cybersecurity roles (target 100%). 5. # cyber incidents reported to NCA within 24h. 6. Third-party compliance rate | AV4: Annual self-assessment (NCA template); NCA external audit (interview + evidence review + technical testing); Penetration test (annual for CNI entities); Configuration review; Access control audit; Social engineering simulation | AW4: IBM OpenPages; ServiceNow GRC; MetricStream; RSA Archer; Nuvolo (OT); NCA self-assessment portal (custom). KSA-specific: NCA compliance tracking platform (government entities). OneTrust for policy management | AX4: ECC-2 Domain 4 (Third-Party & Cloud): mandatory third-party risk assessment before engagement; annual third-party reassessment; contractual ECC compliance obligation in vendor contracts; cloud providers must be NCA-registered; OTCC applies to OT vendors with remote access | AY4: Non-compliance: SAR 25M fine (max); licence suspension; business closure; public naming; criminal referral. Operational impact: NCA can order shutdown of non-compliant systems. Reputational: public disclosure damages patient and investor trust. Competitive: non-compliant health IT vendors excluded from MOH/NUPCO tenders | AZ4: Sector-specific — consult official source | BA4: Sector-Specific | BB4: =IF(E4="","",IF(ISNUMBER(SEARCH("Institutional theory and regulatory governance theory underpin",AI4)),"TEMPLATE",IF(LEN(AI4)>100,"DEEP",IF(AI4="","SPARSE","SHALLOW")))) -> DEEP | BC4: =IF(E4="","",D4&"-"&B4&"-"&E4) -> 3. Cybersecurity & Data-NCA-ECC-2:2024 | BD4: =IF(E4="","",SUBSTITUTE(SUBSTITUTE(B4&"-"&E4," ",""),":","-")) -> NCA-ECC-2-2024 | BE4: =IF(E4="","",IF(ISNUMBER(SEARCH("ECC",E4)),"NCA-ECC-2-2024",IF(ISNUMBER(SEARCH("OTCC",E4)),"NCA-ECC-2-2024",IF(ISNUMBER(SEARCH("CCC",E4)),"NCA-ECC-2-2024",IF(ISNUMBER(SEARCH("DCC",E4)),"NCA-ECC-2-2024",IF(ISNUMBER(SEARCH("CSCC",E4)),"NCA-ECC-2-2024",IF(ISNUMBER(SEARCH("PDPL-IR",E4)),"PDPL-2021",IF(ISNUMBER(SEARCH("PDPL-DTR",E4)),"PDPL-2021","NONE")))))))) -> NCA-ECC-2-2024 | BF4: =IF(E4="","",IF(BB4="DEEP",10,IF(BB4="SHALLOW",5,IF(BB4="TEMPLATE",3,1)))+IF(N4="HIGHEST",5,IF(N4="HIGH",3,IF(N4="MODERATE",1,0)))+IF(ISNUMBER(SEARCH("Mandatory",L4)),3,0)) -> 18
A5: 2 | B5: NCA | C5: National Cybersecurity Authority | D5: 3. Cybersecurity & Data | E5: OTCC-1:2022 | F5: OT Cybersecurity Controls | G5: ضوابط الأمن السيبراني للتقنيات التشغيلية | H5: OTCC-1:2022 | I5: 2022 | J5: 53 | K5: ISSUES/ENFORCES | L5: Mandatory Enforcer | M5: OT/ICS/SCADA incl. medical device networks | N5: HIGHEST | O5: https://nca.gov.sa/otcc_en.pdf | P5: NCA OTCC PDF; Resecurity | Q5: OTCC-1:2022 (First issue) | R5: First dedicated OT/ICS cybersecurity standard for KSA. 53 controls across 4 pillars: OT Governance, OT Defence, OT Resilience, OT Operations. Extends ECC-1:2018 with ICS/SCADA-specific requirements. References IEC 62443 series and NIST SP 800-82. Covers medical device OT networks in hospitals as CNI | S5: Issued: 2022. Compliance mandatory for CNI OT operators | T5: Review expected when ECC-3 released or after 5 years | U5: CURRENT — first and only version | V5: SAR 25M max (NCA-REG-2024 applies); operational shutdown of non-compliant OT systems; CNI operator licence at risk | W5: NCA — OT/ICS specialist inspectors; coordinates with sector regulators (MOH, ECRA, KACARE) for CNI OT audits | X5: Hospital (medical device OT networks); Medical Device Manufacturer; Pharmacy (automated dispensing); Lab (automated systems); Health IT Vendor (OT integration) | Y5: Both (all CNI operators — hospitals qualify as CNI) | Z5: NCA OT assessment; sector-specific OT audit; ICS security assessment by accredited third party | AA5: Biennial NCA assessment; annual internal OT security review | AB5: 53 of 53 — entire framework is OT/ICS applicable; directly covers medical device networks (2-4-x network segmentation; 2-6-x remote access; 2-9-x patch management for OT) | AC5: IEC 62443 (explicit reference); NIST SP 800-82 Rev 3; ISA/IEC 62443-2-1; ISO 27001:2022 (partial) | AD5: Arabic + English (official bilingual) | AE5: Layer 3: Technical Controls (primary); Layer 2: Risk Management; Layer 4: Compliance | AF5: Yes — aligned with IEC 62443 Security Levels (SL1-SL4); OTCC maps to SL2 minimum for healthcare CNI | AG5: National Cybersecurity Strategy; Vision 2030 Healthcare Digital Transformation; HSTP connected medical device targets | AH5: OT asset inventory; network segmentation diagrams; OT patch logs; remote access logs; OT incident response plan; ICS risk assessment report; vendor access audit logs | AI5: Socio-technical systems theory (Trist 1981): OT/IT convergence requires integrated governance. Defence-in-depth (NIST): layered security for critical systems. Critical infrastructure protection theory: availability > confidentiality in OT environments. | AJ5: FOR: First KSA standard addressing ICS/SCADA — fills critical gap identified in Nurse et al. (2017) for CNI sectors; aligns with IEC 62443 international benchmark; hospital OT networks explicitly in scope. AGAINST: Medical IoT falls between OTCC (OT-centric) and ECC-2 (IT-centric) — Coventry & Branley (2018) argue medical devices need dedicated classification not forced into OT/IT binary; OTCC written for industrial OT, clinical environment nuances absent | AK5: Clinical IoMT context absent — infusion pumps and ventilators behave differently from SCADA; no clinical engineering expertise incorporated in drafting; 53 controls insufficient for complex hospital OT topology documented by Jalali & Kaiser (2018); conflict between availability-first OT principle and confidentiality-first healthcare requirement unresolved | AL5: OTCC vs IEC 62443: OTCC mandatory in KSA; IEC 62443 voluntary but globally recognised — OTCC maps to IEC 62443-2-1 security management but lacks 62443-4-2 component-level detail. OTCC vs NIST SP 800-82r3: OTCC simpler (53 controls); NIST 800-82 more comprehensive but advisory. OTCC + SFDA-MDR combined = closest to full IoMT coverage | AM5: Coventry L & Branley D (2018) 'Cybersecurity in Healthcare' BMJ 2018; Jalali MS & Kaiser JP (2018) 'Cybersecurity in Hospitals' JMIR 20(5); Nurse JRC et al. (2017) 'Security Risk Assessment in IoT' IEEE IoT J; NCA (2022) OTCC-1:2022 nca.gov.sa/otcc_en.pdf; ISA/IEC 62443-2-1 (2009) Security Management System for IACS | AN5: Official: OTCC PDF (nca.gov.sa). Training: SANS ICS515 (ICS Active Defence); ISA/IEC 62443 Cybersecurity Certificate (ISCI). Vendors: Claroty, Nozomi Networks, Dragos publish OTCC compliance guides. Estimated: 60 hours (requires ICS/SCADA foundation knowledge first) | AO5: GH-ICGA Layer 3 (Technical Controls) — directly informs IoMT technical control set in preliminary GH-ICGA. Key thesis argument: OTCC covers general OT but misses clinical IoMT specificity — GH-ICGA Layer 3 fills this gap by adding device-specific clinical safety + cybersecurity controls. Referenced in thesis RQ2 on technical governance gaps | AP5: G + C (Governance + Compliance — standard regulatory framework positioning) | AQ5: Senior management: accountability for framework compliance. Designated compliance officer: monitor requirements. All staff: awareness of applicable obligations | AR5: Regulatory Risk; Operational Risk; Reputational Risk — specific domains determined by framework scope | AS5: See official source — legal obligation, regulatory requirement, or voluntary standard as applicable | AT5: Administrative; Technical; Operational — specific distribution determined by framework content | AU5: 1. Compliance status (compliant/non-compliant). 2. # open findings from last assessment. 3. % controls implemented. 4. Time to remediate findings. 5. Incident rate in framework scope area | AV5: Self-assessment; internal audit; external assessment as specified by issuing authority | AW5: ServiceNow GRC; IBM OpenPages; RSA Archer; MetricStream — all major GRC platforms support custom framework import. Contact vendor for framework-specific module | AX5: Third parties in scope must demonstrate equivalent compliance. Contractual compliance obligations; right-to-audit clauses; annual third-party assessment | AY5: Non-compliance: regulatory action by issuing authority; fines and penalties as specified; operational and reputational consequences | AZ5: Sector-specific — consult official source | BA5: Sector-Specific | BB5: =IF(E5="","",IF(ISNUMBER(SEARCH("Institutional theory and regulatory governance theory underpin",AI5)),"TEMPLATE",IF(LEN(AI5)>100,"DEEP",IF(AI5="","SPARSE","SHALLOW")))) -> DEEP | BC5: =IF(E5="","",D5&"-"&B5&"-"&E5) -> 3. Cybersecurity & Data-NCA-OTCC-1:2022 | BD5: =IF(E5="","",SUBSTITUTE(SUBSTITUTE(B5&"-"&E5," ",""),":","-")) -> NCA-OTCC-1-2022 | BE5: =IF(E5="","",IF(ISNUMBER(SEARCH("ECC",E5)),"NCA-ECC-2-2024",IF(ISNUMBER(SEARCH("OTCC",E5)),"NCA-ECC-2-2024",IF(ISNUMBER(SEARCH("CCC",E5)),"NCA-ECC-2-2024",IF(ISNUMBER(SEARCH("DCC",E5)),"NCA-ECC-2-2024",IF(ISNUMBER(SEARCH("CSCC",E5)),"NCA-ECC-2-2024",IF(ISNUMBER(SEARCH("PDPL-IR",E5)),"PDPL-2021",IF(ISNUMBER(SEARCH("PDPL-DTR",E5)),"PDPL-2021","NONE")))))))) -> NCA-ECC-2-2024 | BF5: =IF(E5="","",IF(BB5="DEEP",10,IF(BB5="SHALLOW",5,IF(BB5="TEMPLATE",3,1)))+IF(N5="HIGHEST",5,IF(N5="HIGH",3,IF(N5="MODERATE",1,0)))+IF(ISNUMBER(SEARCH("Mandatory",L5)),3,0)) -> 18
A6: 3 | B6: NCA | C6: National Cybersecurity Authority | D6: 3. Cybersecurity & Data | E6: CCC-1:2020 | F6: Cloud Cybersecurity Controls | G6: ضوابط الأمن السيبراني للحوسبة السحابية | H6: CCC-1:2020 | I6: 2020 | J6: 67 | K6: ISSUES/ENFORCES | L6: Mandatory Enforcer | M6: Cloud service providers and tenants — health cloud platforms | N6: HIGH | O6: https://nca.gov.sa/ccc-en.pdf | P6: NCA CCC PDF; Entrust Nov 2025 | Q6: CCC-1:2020 (First issue); CCC-2 consultation noted 2024/2025 | R6: v1 (2020): 67 controls, 4 domains, 24 sub-domains. Covers CSP and CST obligations. Extends ECC-1:2018 for cloud environments. CSTs must comply with both ECC and CCC. CCC-2 draft noted in 2024/2025 adding edge computing and data localisation controls | S6: CCC-1:2020 mandatory for cloud users/providers since 2020. CCC-2 under consultation 2024-2025 | T6: CCC-2 expected to replace CCC-1 post-consultation | U6: CURRENT — CCC-1:2020. CCC-2 in consultation | V6: SAR 25M max (NCA-REG-2024); cloud service suspension; loss of CSP licence; CST cloud provider licence revoked | W6: NCA (primary cybersecurity oversight); CST (cloud provider licensing); DGA (government cloud governance) | X6: Health IT Vendor (CSP/CST); Hospital (cloud EHR/NABIDH); Health Insurer (cloud claims systems); Government Health Entity | Y6: Both (cloud service providers anywhere + all cloud tenants in KSA) | Z6: Annual CSP self-assessment; NCA cloud audit; CST licensing audit; DGA cloud first policy compliance check | AA6: Annual; CSP external audit every 2 years | AB6: 12 (cloud-hosted IoMT platform controls: data segregation; API security; access management; logging; encryption; incident notification) | AC6: ISO 27017:2015; ISO 27018:2019; ISO 27001:2022; CSA CCM (Cloud Controls Matrix) v4; NIST SP 800-144 | AD6: Arabic + English (official bilingual) | AE6: Layer 3: Technical Controls; Layer 4: Compliance; Layer 2: Risk Management | AF6: Yes — 4 maturity levels for CSPs and CSTs separately | AG6: Cloud First Policy; Vision 2030 Digital Economy; Government Cloud (G-Cloud) initiative | AH6: Cloud architecture diagrams; data classification records; access logs; encryption certificates; CSP audit reports; incident response plan; data residency evidence | AI6: Shared responsibility model (Cloud Security Alliance): CSP vs CST obligation split. Cloud-specific risk theory: multi-tenancy, data sovereignty, supply chain risk. Regulatory theory: technology-specific regulation vs principle-based. | AJ6: FOR: Addresses real gap in ECC-1 for cloud-hosted health systems; CSP+CST dual obligation model mirrors EU NIS2 approach; mandatory for health cloud deployment. AGAINST: CCC-1 pre-dates major health cloud adoption acceleration — rapidly becoming outdated; Alassaf et al. (2019) argue cloud health data sovereignty requirements create innovation friction; CCC-2 consultation process too slow relative to cloud technology evolution | AK6: CCC-1 does not address edge computing (critical for real-time IoMT); generative AI/ML workloads in health cloud not covered; sovereign cloud zone regulations (CST 2023) create regulatory overlap with CCC; NABIDH cloud hosting requirements not explicitly aligned with CCC controls | AL6: CCC vs ISO 27017: CCC mandatory in KSA; ISO 27017 voluntary global standard. CCC maps to CSA CCM v4 (Cloud Controls Matrix) but is simpler. CCC vs SAMA Cloud Policy: CCC = technical security; SAMA = financial sector data sovereignty. Together: CCC + CST-CCR + NCA-ECC = full cloud governance for health entities | AM6: Alassaf N et al. (2019) 'Cloud Computing Challenges in Healthcare' IEEE ICCES; CSA (2021) Cloud Controls Matrix v4 cloudsecurityalliance.org; NCA (2020) CCC-1:2020 nca.gov.sa/ccc-en.pdf; Alhenaki L et al. (2019) 'Security of Cloud Computing' IJACSA 10(7); Alouffi B et al. (2021) 'Systematic Literature Review on Cloud Security' IEEE Access 9 | AN6: Official: NCA CCC PDF. Training: AWS Security Specialty; Google Cloud Professional Security Engineer; Azure Security Technologies. CSA Certificate of Cloud Security Knowledge (CCSK). Estimated: 35 hours | AO6: GH-ICGA Layer 3 (Technical) + Layer 4 (Compliance) — cloud security controls inform GH-ICGA cloud-hosted IoMT governance. Thesis gap: GH-ICGA must address how CCC applies when IoMT data streams to cloud — Layer 3 IoMT Technical Controls include cloud transmission requirements | AP6: R + C (cloud-specific risk and compliance) | AQ6: CTO/Cloud Owner: responsible for CCC compliance. Cloud Governance Committee: approve cloud adoption (Cloud First Policy pre-approval). CISO: ensure CSP selection meets CCC requirements. CSP relationship owner: maintain contractual CCC compliance | AR6: Cyber Risk (cloud-specific); Data Sovereignty Risk; Supply Chain Risk (CSP); Operational Risk (cloud outage); Regulatory Risk (data localisation) | AS6: LEGAL — Mandatory for all ECC-scope entities using cloud + all CSPs operating in KSA. Integrated with NCA-ECC-2 compliance. NCA-REG-2024 enforcement applies | AT6: Technical: 50 controls — data encryption; access management; API security; network controls; logging. Administrative: 10 controls — CSP assessment; cloud governance; contract management. Operational: 7 controls — cloud incident response; CSP SLA management | AU6: 1. % cloud workloads with encryption at rest and in transit. 2. # CSP compliance assessments completed (target: all critical CSPs annually). 3. Cloud incident response time (target <1h detection, <4h notification). 4. % data classified and labelled in cloud. 5. CSP CCC compliance score | AV6: CSP CCC compliance assessment (annual); cloud configuration review (CSPM tools); cloud penetration test; data residency verification; access management audit; API security scan | AW6: Palo Alto Prisma Cloud; Microsoft Defender for Cloud; AWS Security Hub; Google Chronicle; Wiz; CSPM (Cloud Security Posture Management) tools. For KSA: cloud brokers with local data centre: STC Cloud; Mobily Cloud; Oracle KSA; AWS Bahrain region | AX6: All CSPs: must demonstrate NCA CCC compliance; data residency within KSA (government data); PDPL-DTR-2024 cross-border assessment; annual CSP security report; right-to-audit clause; incident notification within 4 hours; subprocessor disclosure | AY6: Non-compliance: NCA audit finding; SAR 25M fine; cloud service suspension by CST. Data breach in cloud: PDPL + CCC dual penalties; CSP liability; patient data exposure | AZ6: Sector-specific — consult official source | BA6: Sector-Specific | BB6: =IF(E6="","",IF(ISNUMBER(SEARCH("Institutional theory and regulatory governance theory underpin",AI6)),"TEMPLATE",IF(LEN(AI6)>100,"DEEP",IF(AI6="","SPARSE","SHALLOW")))) -> DEEP | BC6: =IF(E6="","",D6&"-"&B6&"-"&E6) -> 3. Cybersecurity & Data-NCA-CCC-1:2020 | BD6: =IF(E6="","",SUBSTITUTE(SUBSTITUTE(B6&"-"&E6," ",""),":","-")) -> NCA-CCC-1-2020 | BE6: =IF(E6="","",IF(ISNUMBER(SEARCH("ECC",E6)),"NCA-ECC-2-2024",IF(ISNUMBER(SEARCH("OTCC",E6)),"NCA-ECC-2-2024",IF(ISNUMBER(SEARCH("CCC",E6)),"NCA-ECC-2-2024",IF(ISNUMBER(SEARCH("DCC",E6)),"NCA-ECC-2-2024",IF(ISNUMBER(SEARCH("CSCC",E6)),"NCA-ECC-2-2024",IF(ISNUMBER(SEARCH("PDPL-IR",E6)),"PDPL-2021",IF(ISNUMBER(SEARCH("PDPL-DTR",E6)),"PDPL-2021","NONE")))))))) -> NCA-ECC-2-2024 | BF6: =IF(E6="","",IF(BB6="DEEP",10,IF(BB6="SHALLOW",5,IF(BB6="TEMPLATE",3,1)))+IF(N6="HIGHEST",5,IF(N6="HIGH",3,IF(N6="MODERATE",1,0)))+IF(ISNUMBER(SEARCH("Mandatory",L6)),3,0)) -> 16
A7: 4 | B7: NCA | C7: National Cybersecurity Authority | D7: 3. Cybersecurity & Data | E7: DCC-1:2022 | F7: Data Cybersecurity Controls | G7: ضوابط أمن البيانات | H7: DCC-1:2022 | I7: 2022 | J7: 40 | K7: ISSUES/ENFORCES | L7: Mandatory Enforcer | M7: All ECC-scope entities — patient data lifecycle | N7: HIGH | O7: https://nca.gov.sa/ | P7: Resecurity; NCA official | Q7: DCC-1:2022 (First issue) | R7: First dedicated data cybersecurity controls from NCA. 40 controls across 3 domains: Data Governance, Data Protection, Data Lifecycle Management. Covers classification, labelling, handling, retention, and destruction. Aligns with NDMO Data Classification Policy and PDPL requirements | S7: Issued: 2022. Mandatory for all ECC-scope entities | T7: Review expected 2025-2026 | U7: CURRENT — first and only version | V7: SAR 25M max (NCA-REG-2024); PDPL penalties also applicable for personal data; data processing suspension | W7: NCA (technical data security); SDAIA/NDMO (personal data governance overlap) | X7: Hospital; Lab; Health IT Vendor; Health Insurer; Government Health Entity (all data processors) | Y7: Both | Z7: NCA annual self-assessment; may be assessed jointly with ECC audit | AA7: Annual (integrated with ECC self-assessment cycle) | AB7: 15 (IoMT data lifecycle: collection minimisation; storage encryption; transmission security; retention and secure disposal of device-generated data) | AC7: ISO 27001:2022 Annex A (data protection controls); NIST SP 800-53r5 (data protection family); GDPR (partial reference) | AD7: Arabic + English | AE7: Layer 3: Technical Controls; Layer 4: Compliance | AF7: Yes — 4 maturity levels aligned with ECC maturity model | AG7: National Data Strategy; PDPL implementation support; Vision 2030 digital trust | AH7: Data classification register; encryption implementation evidence; data retention policy; secure disposal records; data flow maps | AI7: Institutional theory and regulatory governance theory underpin all KSA regulatory frameworks. Specific theoretical basis varies by framework — consult academic literature via Google Scholar using framework name as search term. | AJ7: Academic debate varies by framework maturity and international adoption. For KSA-specific debate, consult: Almohammad & Wills (2021) J Cybersecurity; Al-Khater et al. (2020) IEEE Access; Baker McKenzie KSA regulatory updates. | AK7: Known criticisms include: implementation gap between standards and practice; resource constraints for smaller healthcare entities; rapid technology evolution outpacing regulation. Consult framework evaluation literature for specifics. | AL7: Framework comparison requires contextual analysis. Key comparators: NIST CSF 2.0 (international benchmark), ISO 27001 (certifiable standard), ECC-2 (KSA mandatory baseline). See main database for cross-framework mapping. | AM7: Key foundational references: Almohammad A & Wills G (2021) J Cybersecurity; NIST (2024) CSF 2.0; ISO (2022) 27001; NCA official documents (nca.gov.sa); Baker McKenzie Global Data & Cyber Handbook 2025. Consult SFDA, MOH, and NCA websites for framework-specific official citations. | AN7: Official: Consult the official source URL in the database for the primary document. Training: ISACA, ISC2, RAPS, IAPP, and HIMSS offer professional development covering most regulatory domains. Estimated hours vary by framework complexity. | AO7: Relevance to GH-ICGA framework varies by layer — see GH-ICGA Layer Mapping column. All KSA mandatory frameworks are compliance inputs to GH-ICGA Layer 4. Frameworks with IoMT-specific provisions directly inform Layers 2 and 3. | AP7: G + C (Governance + Compliance — standard regulatory framework positioning) | AQ7: Senior management: accountability for framework compliance. Designated compliance officer: monitor requirements. All staff: awareness of applicable obligations | AR7: Regulatory Risk; Operational Risk; Reputational Risk — specific domains determined by framework scope | AS7: See official source — legal obligation, regulatory requirement, or voluntary standard as applicable | AT7: Administrative; Technical; Operational — specific distribution determined by framework content | AU7: 1. Compliance status (compliant/non-compliant). 2. # open findings from last assessment. 3. % controls implemented. 4. Time to remediate findings. 5. Incident rate in framework scope area | AV7: Self-assessment; internal audit; external assessment as specified by issuing authority | AW7: ServiceNow GRC; IBM OpenPages; RSA Archer; MetricStream — all major GRC platforms support custom framework import. Contact vendor for framework-specific module | AX7: Third parties in scope must demonstrate equivalent compliance. Contractual compliance obligations; right-to-audit clauses; annual third-party assessment | AY7: Non-compliance: regulatory action by issuing authority; fines and penalties as specified; operational and reputational consequences | AZ7: Sector-specific — consult official source | BA7: Sector-Specific | BB7: =IF(E7="","",IF(ISNUMBER(SEARCH("Institutional theory and regulatory governance theory underpin",AI7)),"TEMPLATE",IF(LEN(AI7)>100,"DEEP",IF(AI7="","SPARSE","SHALLOW")))) -> TEMPLATE | BC7: =IF(E7="","",D7&"-"&B7&"-"&E7) -> 3. Cybersecurity & Data-NCA-DCC-1:2022 | BD7: =IF(E7="","",SUBSTITUTE(SUBSTITUTE(B7&"-"&E7," ",""),":","-")) -> NCA-DCC-1-2022 | BE7: =IF(E7="","",IF(ISNUMBER(SEARCH("ECC",E7)),"NCA-ECC-2-2024",IF(ISNUMBER(SEARCH("OTCC",E7)),"NCA-ECC-2-2024",IF(ISNUMBER(SEARCH("CCC",E7)),"NCA-ECC-2-2024",IF(ISNUMBER(SEARCH("DCC",E7)),"NCA-ECC-2-2024",IF(ISNUMBER(SEARCH("CSCC",E7)),"NCA-ECC-2-2024",IF(ISNUMBER(SEARCH("PDPL-IR",E7)),"PDPL-2021",IF(ISNUMBER(SEARCH("PDPL-DTR",E7)),"PDPL-2021","NONE")))))))) -> NCA-ECC-2-2024 | BF7: =IF(E7="","",IF(BB7="DEEP",10,IF(BB7="SHALLOW",5,IF(BB7="TEMPLATE",3,1)))+IF(N7="HIGHEST",5,IF(N7="HIGH",3,IF(N7="MODERATE",1,0)))+IF(ISNUMBER(SEARCH("Mandatory",L7)),3,0)) -> 9
