Workbook

Sheet KSA — Regulator Master
A1: 🇸🇦 KSA GRC REGULATOR MASTER CATALOGUE · Local (60+) + International (15) = 75+ Active Regulators in KSA
A2: LOCAL REGULATORS · Tier 1 (Primary) + Tier 2 (Sector) + Tier 3 (Specialised)
A3: Code | B3: Name (EN) | C3: Name (AR) | D3: Sector Group | E3: Tier | F3: Own Frameworks | G3: Power Index (0-100) | H3: Enforcement | I3: Key Frameworks | J3: Mandatory for | K3: Saudisation? | L3: Website | M3: Sectors Covered | N3: Annual Compliance Cost (Est.) | O3: Notes
A4: NCA | B4: National Cybersecurity Authority | C4: الهيئة الوطنية للأمن السيبراني | D4: Cybersecurity | E4: 🔴 T1 | F4: 7 | G4: 98 | H4: MANDATORY | I4: - | J4: Sector-dependent | K4: Yes (where applicable) | L4: https://nca.gov.sa | M4: - | N4: - | O4: Issues ECC, OTCC, CCC, DCC, CSCC
A5: SDAIA | B5: Saudi Data & AI Authority | C5: هيئة البيانات والذكاء الاصطناعي | D5: Data/AI | E5: 🔴 T1 | F5: 5 | G5: 95 | H5: MANDATORY | I5: - | J5: Sector-dependent | K5: Yes (where applicable) | L5: https://sdaia.gov.sa | M5: - | N5: - | O5: PDPL regulator, AI strategy
A6: SAMA | B6: Saudi Arabian Monetary Authority | C6: البنك المركزي السعودي | D6: Financial | E6: 🔴 T1 | F6: 8 | G6: 98 | H6: MANDATORY | I6: - | J6: Sector-dependent | K6: Yes (where applicable) | L6: https://sama.gov.sa | M6: - | N6: - | O6: Banks, insurance, payments, fintechs
A7: CMA | B7: Capital Market Authority | C7: هيئة السوق المالية | D7: Capital Markets | E7: 🔴 T1 | F7: 5 | G7: 90 | H7: MANDATORY | I7: - | J7: Sector-dependent | K7: Yes (where applicable) | L7: https://cma.org.sa | M7: - | N7: - | O7: Tadawul, listed cos, investment funds
A8: CITC | B8: Communications & IT Commission | C8: هيئة الاتصالات وتقنية المعلومات | D8: ICT/Telecom | E8: 🔴 T1 | F8: 4 | G8: 88 | H8: MANDATORY | I8: - | J8: Sector-dependent | K8: Yes (where applicable) | L8: https://citc.gov.sa | M8: - | N8: - | O8: Telecom licensing, digital services
A9: SFDA | B9: Saudi Food & Drug Authority | C9: الهيئة العامة للغذاء والدواء | D9: Healthcare/Pharma | E9: 🔴 T1 | F9: 6 | G9: 87 | H9: MANDATORY | I9: - | J9: Sector-dependent | K9: Yes (where applicable) | L9: https://sfda.gov.sa | M9: - | N9: - | O9: Medical devices, pharma, food safety
A10: MOH | B10: Ministry of Health | C10: وزارة الصحة | D10: Healthcare | E10: 🔴 T1 | F10: 5 | G10: 85 | H10: MANDATORY | I10: - | J10: Sector-dependent | K10: Yes (where applicable) | L10: https://moh.gov.sa | M10: - | N10: - | O10: Hospital standards, HIS, patient data
A11: ZATCA | B11: Zakat, Tax & Customs Authority | C11: هيئة الزكاة والضريبة والجمارك | D11: Tax/Customs | E11: 🔴 T1 | F11: 4 | G11: 90 | H11: MANDATORY | I11: - | J11: Sector-dependent | K11: Yes (where applicable) | L11: https://zatca.gov.sa | M11: - | N11: - | O11: VAT, e-invoicing (Fatoorah), customs
A12: MHRSD | B12: Ministry of HR & Social Development | C12: وزارة الموارد البشرية والتنمية الاجتماعية | D12: Labour | E12: 🔴 T1 | F12: 3 | G12: 80 | H12: MANDATORY | I12: - | J12: Sector-dependent | K12: Yes (where applicable) | L12: https://mhrsd.gov.sa | M12: - | N12: - | O12: Nitaqat, Saudisation, labour contracts
A13: MOI | B13: Ministry of Interior | C13: وزارة الداخلية | D13: Security/CNI | E13: 🔴 T1 | F13: 2 | G13: 95 | H13: MANDATORY | I13: - | J13: Sector-dependent | K13: Yes (where applicable) | L13: https://moi.gov.sa | M13: - | N13: - | O13: CNI protection, national security
A14: CCHI | B14: Council of Cooperative Health Insurance | C14: مجلس الضمان الصحي التعاوني | D14: Healthcare Insurance | E14: 🟠 T2 | F14: 3 | G14: 82 | H14: MANDATORY | I14: - | J14: Sector-dependent | K14: Yes (where applicable) | L14: https://cchi.gov.sa | M14: - | N14: - | O14: Health insurance mandates
A15: CBAHI | B15: Central Board for Accreditation of HCI | C15: المركز السعودي لاعتماد المنشآت الصحية | D15: Healthcare Accred. | E15: 🟠 T2 | F15: 3 | G15: 78 | H15: MANDATORY | I15: - | J15: Sector-dependent | K15: Yes (where applicable) | L15: https://cbahi.gov.sa | M15: - | N15: - | O15: Hospital accreditation standards
A16: GAHAR | B16: General Authority for Healthcare Accreditation & Research | C16: الهيئة العامة للاعتماد وتقييم المنشآت الصحية | D16: Healthcare | E16: 🟠 T2 | F16: 2 | G16: 75 | H16: MANDATORY | I16: - | J16: Sector-dependent | K16: Yes (where applicable) | L16: https://gahar.gov.sa | M16: - | N16: - | O16: Quality & patient safety
A17: SCA | B17: Saudi Contractors Authority | C17: هيئة المقاولين | D17: Construction | E17: 🟠 T2 | F17: 2 | G17: 55 | H17: MANDATORY | I17: - | J17: Sector-dependent | K17: Yes (where applicable) | M17: - | N17: -
A18: NCSC | B18: National Cybersecurity Committee (Ops) | C18: اللجنة الوطنية للأمن السيبراني | D18: Cybersecurity Ops | E18: 🟠 T2 | F18: 1 | G18: 70 | H18: MANDATORY | I18: - | J18: Sector-dependent | K18: Yes (where applicable) | M18: - | N18: - | O18: Coordinates with NCA
A19: NDMO | B19: National Data Management Office | C19: مكتب إدارة البيانات الوطني | D19: Data Gov. | E19: 🟠 T2 | F19: 2 | G19: 72 | H19: MANDATORY | I19: - | J19: Sector-dependent | K19: Yes (where applicable) | L19: https://ndmo.gov.sa | M19: - | N19: - | O19: Data governance policy (under SDAIA)
A20: MISA | B20: Ministry of Investment | C20: وزارة الاستثمار | D20: Investment | E20: 🟠 T2 | F20: 1 | G20: 65 | H20: MANDATORY | I20: - | J20: Sector-dependent | K20: Yes (where applicable) | L20: https://misa.gov.sa | M20: - | N20: - | O20: Foreign investment, economic zones
A21: DGA | B21: Digital Government Authority | C21: هيئة الحكومة الرقمية | D21: Digital Gov. | E21: 🟠 T2 | F21: 3 | G21: 78 | H21: MANDATORY | I21: - | J21: Sector-dependent | K21: Yes (where applicable) | L21: https://dga.gov.sa | M21: - | N21: - | O21: Gov cloud, digital transformation
A22: MCIT | B22: Ministry of Communications & IT | C22: وزارة الاتصالات وتقنية المعلومات | D22: ICT | E22: 🟠 T2 | F22: 3 | G22: 75 | H22: MANDATORY | I22: - | J22: Sector-dependent | K22: Yes (where applicable) | L22: https://mcit.gov.sa | M22: - | N22: - | O22: Digital economy strategy
A23: MOE_ED | B23: Ministry of Education | C23: وزارة التعليم | D23: Education | E23: 🟠 T2 | F23: 2 | G23: 60 | H23: MANDATORY | I23: - | J23: Sector-dependent | K23: Yes (where applicable) | L23: https://moe.gov.sa | M23: - | N23: - | O23: EdTech, student data protection
A24: MOJ | B24: Ministry of Justice | C24: وزارة العدل | D24: Legal | E24: 🟠 T2 | F24: 2 | G24: 70 | H24: MANDATORY | I24: - | J24: Sector-dependent | K24: Yes (where applicable) | L24: https://moj.gov.sa | M24: - | N24: - | O24: Electronic transactions, Notary
A25: MOF | B25: Ministry of Finance | C25: وزارة المالية | D25: Public Finance | E25: 🟠 T2 | F25: 2 | G25: 75 | H25: MANDATORY | I25: - | J25: Sector-dependent | K25: Yes (where applicable) | L25: https://mof.gov.sa | M25: - | N25: - | O25: Gov procurement, IPSAS
A26: ECRA | B26: Electricity & Cogeneration Regulatory Authority | C26: هيئة تنظيم الكهرباء | D26: Energy | E26: 🟠 T2 | F26: 3 | G26: 72 | H26: MANDATORY | I26: - | J26: Sector-dependent | K26: Yes (where applicable) | L26: https://ecra.gov.sa | M26: - | N26: - | O26: Power grid, renewable energy
A27: NCPD | B27: National Center for Privatization & PPP | C27: المركز الوطني للتخصيص والشراكة | D27: PPP/Privatisation | E27: 🟠 T2 | F27: 1 | G27: 58 | H27: MANDATORY | I27: - | J27: Sector-dependent | K27: Yes (where applicable) | M27: - | N27: -
A28: GAC | B28: General Authority of Customs | C28: الهيئة العامة للجمارك | D28: Customs | E28: 🟠 T2 | F28: 2 | G28: 70 | H28: MANDATORY | I28: - | J28: Sector-dependent | K28: Yes (where applicable) | L28: https://gca.gov.sa | M28: - | N28: - | O28: Trade compliance, AEO
A29: GOSI | B29: General Organisation for Social Insurance | C29: المؤسسة العامة للتأمينات الاجتماعية | D29: Social Insurance | E29: 🟠 T2 | F29: 2 | G29: 68 | H29: MANDATORY | I29: - | J29: Sector-dependent | K29: Yes (where applicable) | L29: https://gosi.gov.sa | M29: - | N29: - | O29: Pension, work injury
A30: ETEC | B30: Education Evaluation & Training Accreditation Commission | C30: المركز الوطني للتقويم والاعتماد الأكاديمي | D30: Education Accred. | E30: 🟠 T2 | F30: 2 | G30: 55 | H30: MANDATORY | I30: - | J30: Sector-dependent | K30: Yes (where applicable) | M30: - | N30: -
A31: SCFHS | B31: Saudi Commission for Health Specialties | C31: الهيئة السعودية للتخصصات الصحية | D31: Health Workforce | E31: 🟠 T2 | F31: 2 | G31: 62 | H31: MANDATORY | I31: - | J31: Sector-dependent | K31: Yes (where applicable) | L31: https://scfhs.org.sa | M31: - | N31: - | O31: Health professional licensing
A32: SCTH | B32: Saudi Commission for Tourism & National Heritage | C32: الهيئة السعودية للسياحة | D32: Tourism | E32: 🟠 T2 | F32: 1 | G32: 45 | H32: MANDATORY | I32: - | J32: Sector-dependent | K32: Yes (where applicable) | M32: - | N32: -
A33: GACA | B33: General Authority of Civil Aviation | C33: الهيئة العامة للطيران المدني | D33: Aviation | E33: 🟠 T2 | F33: 3 | G33: 78 | H33: MANDATORY | I33: - | J33: Sector-dependent | K33: Yes (where applicable) | L33: https://gaca.gov.sa | M33: - | N33: - | O33: ICAO compliance, aviation safety
A34: MAWANI | B34: Saudi Ports Authority | C34: الهيئة العامة للموانئ | D34: Maritime/Ports | E34: 🟠 T2 | F34: 2 | G34: 62 | H34: MANDATORY | I34: - | J34: Sector-dependent | K34: Yes (where applicable) | L34: https://mawani.gov.sa | M34: - | N34: - | O34: Port operations, trade
A35: MOT | B35: Ministry of Transport | C35: وزارة النقل | D35: Transport | E35: 🟠 T2 | F35: 2 | G35: 65 | H35: MANDATORY | I35: - | J35: Sector-dependent | K35: Yes (where applicable) | L35: https://mot.gov.sa | M35: - | N35: - | O35: Road, rail, logistics
A36: WERA | B36: Water & Electricity Regulatory Authority | C36: الهيئة التنظيمية للمياه والكهرباء | D36: Water/Energy | E36: 🟠 T2 | F36: 2 | G36: 65 | H36: MANDATORY | I36: - | J36: Sector-dependent | K36: Yes (where applicable) | L36: https://wera.gov.sa | M36: - | N36: - | O36: Utility regulation
A37: NHC | B37: National Housing Company | C37: الشركة الوطنية للإسكان | D37: Real Estate | E37: 🟠 T2 | F37: 1 | G37: 50 | H37: MANDATORY | I37: - | J37: Sector-dependent | K37: Yes (where applicable) | M37: - | N37: -
A38: MOMRAH | B38: Ministry of Municipal & Rural Affairs & Housing | C38: وزارة الشؤون البلدية والقروية والإسكان | D38: Municipal | E38: 🟠 T2 | F38: 2 | G38: 55 | H38: MANDATORY | I38: - | J38: Sector-dependent | K38: Yes (where applicable) | M38: - | N38: -
A39: GASTAT | B39: General Authority for Statistics | C39: الهيئة العامة للإحصاء | D39: Statistics | E39: 🟠 T2 | F39: 1 | G39: 48 | H39: MANDATORY | I39: - | J39: Sector-dependent | K39: Yes (where applicable) | L39: https://stats.gov.sa | M39: - | N39: - | O39: Data sharing, national statistics
A40: NAZAHA | B40: National Anti-Corruption Commission | C40: هيئة الرقابة ومكافحة الفساد – نزاهة | D40: Anti-Corruption | E40: 🟠 T2 | F40: 2 | G40: 82 | H40: MANDATORY | I40: - | J40: Sector-dependent | K40: Yes (where applicable) | L40: https://nazaha.gov.sa | M40: - | N40: - | O40: Whistleblowing, integrity
...

Sheet KSA — GRC Dashboard
A1: 🇸🇦 SHAHIN-AI · KSA GRC INTELLIGENCE DASHBOARD · Full Regulatory Universe
A3: Total Regulators in KSA | D3: 60 local + 15 international = 75 total
A4: Tier 1 (Critical Power) | D4: 10 local primary regulators
A5: Tier 2 (Sector) | D5: 37 sector-level regulators
A6: International Bodies Active in KSA | D6: 15 (FATF, Basel, IOSCO, SWIFT, ISO, IEC, etc.)
A7: KSA Frameworks (key) | D7: 23 documented key frameworks
A8: Total Control Count (KSA) | D8: 28,239 individual controls (from 405 frameworks)
A9: Sectors Covered | D9: 13 sectors with full regulatory mapping
A10: Org Types Mapped | D10: 12 organisation types with obligation matrix
A11: Org Size Tiers | D11: 6 tiers (Micro → SIFI) with cost/burden estimates
A12: Risk Domains Tracked | D12: 12 risk domains with KRIs and thresholds
A13: Evidence Types Required | D13: 15 types of compliance evidence
A16: KSA SECTOR SUMMARY
A17: Sector | B17: Emoji | C17: Local Regs | D17: Intl Regs | E17: Total Regs | F17: Key Frameworks | G17: Controls | H17: Risk Level | I17: IoT Intensity | J17: Risk Score
A18: Financial Services | B18: 🏦 | C18: 3 | D18: 7 | E18: 10 | F18: 8 | G18: 387 | H18: CRITICAL | I18: LOW | J18: 740
A19: Healthcare & Life Sciences | B19: 🏥 | C19: 7 | D19: 3 | E19: 10 | F19: 8 | G19: 298 | H19: CRITICAL | I19: HIGHEST | J19: 746
A20: Cybersecurity & Data | B20: 🔒 | C20: 4 | D20: 3 | E20: 7 | F20: 7 | G20: 358 | H20: CRITICAL | I20: HIGHEST | J20: 493
A21: ICT / Digital / Telecom | B21: 📡 | C21: 4 | D21: 2 | E21: 6 | F21: 6 | G21: 245 | H21: HIGH | I21: HIGH | J21: 493
A22: Energy & Utilities | B22: ⚡ | C22: 5 | D22: 2 | E22: 7 | F22: 6 | G22: 223 | H22: CRITICAL | I22: HIGHEST | J22: 673
A23: Government & Public Sector | B23: 🏛️ | C23: 6 | D23: 1 | E23: 7 | F23: 6 | G23: 305 | H23: CRITICAL | I23: MODERATE | J23: 648
A24: Tax / Customs / Trade | B24: 📋 | C24: 3 | D24: 2 | E24: 5 | F24: 5 | G24: 115 | H24: HIGH | I24: LOW | J24: 585
A25: Standards & Quality | B25: ✅ | C25: 2 | D25: 2 | E25: 4 | F25: 4 | G25: 85 | H25: MEDIUM | I25: LOW | J25: 493
A26: Transport & Logistics | B26: 🚢 | C26: 4 | D26: 1 | E26: 5 | F26: 4 | G26: 132 | H26: HIGH | I26: HIGH | J26: 493
A27: Industry & Manufacturing | B27: 🏭 | C27: 4 | D27: 2 | E27: 6 | F27: 5 | G27: 145 | H27: HIGH | I27: HIGH | J27: 588
A28: Education & Research | B28: 🎓 | C28: 4 | D28: 1 | E28: 5 | F28: 4 | G28: 95 | H28: MEDIUM | I28: MODERATE | J28: 493
A29: Legal & Anti-Corruption | B29: ⚖️ | C29: 3 | D29: 1 | E29: 4 | F29: 4 | G29: 68 | H29: HIGH | I29: LOW | J29: 493
A30: Giga & Special Zones | B30: 🌆 | C30: 5 | D30: 2 | E30: 7 | F30: 4 | G30: 178 | H30: HIGH | I30: HIGHEST | J30: 585
A34: NAVIGATION — DRILL-DOWN SHEETS IN THIS WORKBOOK
A35: → KSA — Regulator Master | B35: All 75 regulators: local + international, tiers, power index, frameworks
A36: → KSA — Sector Drill-Down | B36: All 13 sectors: per sector regulators, frameworks, evidence, risk
A37: → KSA — Org Type Matrix | B37: All 12 org types: obligation matrix, CISO/DPO/MLRO requirements
A38: → KSA — Org Size Guide | B38: All 6 size tiers: compliance cost, controls, audit requirements
A39: → KSA — Framework Master | B39: All 23 key frameworks: domains, controls, evidence, risk, effective date
A40: → KSA — Evidence Matrix | B40: All 15 evidence types × org type cross-reference
A41: → KSA — Risk Matrix | B41: All 12 risk domains: heat map, KRIs, thresholds, escalation

Sheet Navigation Hub
A1: 🏠 KSA GRC KNOWLEDGE BASE — NAVIGATION HUB
A2: The Most Comprehensive GRC Intelligence Platform for Saudi Arabia • 108 Regulators • 452 Frameworks • 28,000+ Controls
A4: 📚 CORE DATA SHEETS
A5: # | B5: Sheet Name | C5: Description | D5: Rows | E5: Purpose
A6: 1 | B6: All 108 Regulators - Frameworks | C6: Master database: 452 framework entries across 53 data dimensions per framework | D6: 452 | E6: 💾 Primary data source — DO NOT MODIFY structure
A7: 2 | B7: Per-Regulator Summary | C7: 107 regulators with framework count, codes, HC IoT ranking | D7: 107 | E7: 📊 Regulator-level aggregation
A8: 3 | B8: HC IoT Priority Ranked | C8: 339 frameworks ranked by Healthcare IoT relevance | D8: 339 | E8: 🏥 Healthcare IoT focus ranking
A9: 4 | B9: Version Details Reference | C9: 191 version history entries with change details | D9: 191 | E9: 📅 Version tracking and change history
A10: 5 | B10: HC IoT Compliance Checklist | C10: 64-item compliance checklist for healthcare IoT | D10: 64 | E10: ✅ Practical compliance checklist
A12: 🔬 ANALYSIS & INTELLIGENCE SHEETS
A13: 6 | B13: GRC Intelligence Engine | C13: 🆕 Automated scoring: KPIs, Power Index, IoT distribution, Velocity, Maturity gaps | D13: 210+ | E13: 🧠 Analytics engine — auto-updates from master data
A14: 7 | B14: Executive Command Centre | C14: 🆕 Visual dashboard with 4 charts, 7 KPI cards, auto-calculated metrics | D14: N/A | E14: 📊 Executive presentation — charts auto-refresh
A15: 8 | B15: GRC Linkage Engine | C15: 🆕 Unified 9-dimension traceability: Controls ↔ Evidence ↔ Risk ↔ Lifecycle ↔ Policy ↔ Treatment ↔ Org Size ↔ Regulatory ↔ Sector | D15: 135+ | E15: 🔗 End-to-end GRC operating model — connective tissue
A16: 8 | B16: Risk Domain Coverage Matrix | C16: Framework × Risk Domain mapping with coverage scores | D16: 25 | E16: 🎯 Risk coverage analysis
A17: 9 | B17: Sector × Framework Matrix | C17: 17 sectors × frameworks applicability matrix | D17: 33 | E17: 🟢 Sector coverage map
A18: 10 | B18: Framework Debate Matrix | C18: Academic for/against analysis per framework with citations | D18: 191 | E18: 🎓 Academic positioning
A19: 11 | B19: KSA GRC Architecture Map | C19: Layer-by-layer GRC ecosystem with dependencies and conflicts | D19: 36 | E19: 🏗️ Architecture blueprint
A21: 🎯 OPERATIONAL SHEETS
A22: 12 | B22: Audit Universe (All Sectors) | C22: 49 audit areas with risk ratings, frequency, evidence requirements | D22: 49 | E22: 🔎 Audit planning
A23: 13 | B23: KRI Dashboard (All Sectors) | C23: 42 Key Risk Indicators with Green/Amber/Red thresholds and benchmarks | D23: 42 | E23: 🚦 Risk monitoring
A24: 14 | B24: GRC Maturity (All Sectors) | C24: 9 GRC domains × 5 maturity levels with evidence requirements | D24: 9 | E24: 📈 Maturity assessment
A25: 15 | B25: Compliance Calculator | C25: 🆕 Input sector/entity → auto-generates applicable frameworks, controls, audits | D25: Dynamic | E25: 🧮 Interactive compliance tool
A27: 🌐 STRATEGIC & EXTENSIBILITY SHEETS
A28: 16 | B28: Global GRC Benchmark | C28: 🆕 KSA vs international frameworks (EU, US, UK, UAE, ISO) | D28: TBD | E28: 🌍 International positioning
A29: 17 | B29: Regulatory Change Log | C29: 🆕 Version tracking with dropdown status, impact, deadlines | D29: Extensible | E29: 📝 Change management
A30: 18 | B30: Framework Dependencies | C30: 🆕 Cross-framework relationship map: extends, overlaps, conflicts | D30: 14+ | E30: 🔗 Dependency mapping
A32: 🎓 KNOWLEDGE & LEARNING SHEETS
A33: 19 | B33: Knowledge Foundation | C33: 10 theoretical frameworks underpinning KSA GRC: governance theory, institutional theory, risk mgmt | D33: 10 | E33: 📚 Academic theory base
A34: 20 | B34: Learning Pathway | C34: 26-step learning pathway from foundation to expert | D34: 26 | E34: 🎓 Professional development
A35: 21 | B35: GH-ICGA Positioning Matrix | C35: 5-layer GH-ICGA framework positioning with academic research gaps | D35: 5 | E35: 🎯 Thesis positioning
A36: 22 | B36: Content Eval & Shahin-AI | C36: 🆕 Full evaluation: 10-dimension scoring, AI architecture, RAG chunking spec, 8 MCP endpoints, improvement roadmap | D36: 145+ | E36: 🧪 Combined human + AI optimisation report
A37: Last Updated: April 2026 • Built for GH-ICGA Doctoral Research • © KSA GRC Knowledge Base

Sheet GRC Linkage Engine
A1: 🔗 GRC LINKAGE ENGINE — UNIFIED CONTROL-TO-SECTOR TRACEABILITY
A2: Controls ↔ Evidence ↔ Risk ↔ Lifecycle ↔ Policy ↔ Treatment ↔ Org Size ↔ KSA Regulatory ↔ Sector • End-to-end GRC operating model
A4: ━━━ SECTION A: CONTROL-TO-EVIDENCE MATRIX ━━━
A5: Link ID | B5: Framework | C5: Control Category | D5: Control Domain | E5: Evidence Type Required | F5: Evidence Examples | G5: Evidence Retention | H5: → Risk if Missing
A6: CE-001 | B6: NCA-ECC-2:2024 | C6: Administrative (A) | D6: Governance & Leadership (A.1) | E6: Policy Document | F6: Board-approved cybersecurity strategy; CISO appointment letter; cyber committee TOR; governance framework document | G6: 5 years | H6: → RISK-001: Governance failure → NCA non-compliance → SAR 25M fine
A7: CE-002 | B7: NCA-ECC-2:2024 | C7: Administrative (A) | D7: Workforce & Saudisation (A.2) | E7: HR Records + Certificates | F7: Saudi national ID verification for cyber roles; NCA-recognised CISO certification; Qiwa Saudisation report; GOSI registration proof | G7: Duration + 3yr | H7: → RISK-002: Saudisation breach → Nitaqat Red zone + ECC-2 non-compliance
A8: CE-003 | B8: NCA-ECC-2:2024 | C8: Administrative (A) | D8: Training & Awareness (A.3) | E8: Training Records | F8: Annual awareness completion logs; phishing simulation results; role-based training certificates; social engineering test reports | G8: 3 years | H8: → RISK-003: Human factor vulnerability → breach likelihood increases 4×
A9: CE-004 | B9: NCA-ECC-2:2024 | C9: Technical (T) | D9: Access Control (T.1) | E9: System Configuration + Logs | F9: IAM policy; MFA deployment evidence; privileged access reviews (quarterly); access recertification; segregation of duties matrix | G9: 3 years | H9: → RISK-004: Unauthorised access → data breach → PDPL + NCA dual penalty
A10: CE-005 | B10: NCA-ECC-2:2024 | C10: Technical (T) | D10: Network Security (T.2) | E10: Architecture Diagram + Scans | F10: Network segmentation diagram; firewall rulesets; IDS/IPS alerts; penetration test report (annual); vulnerability scan (monthly) | G10: 3 years | H10: → RISK-005: Network compromise → lateral movement → CNI disruption
A11: CE-006 | B11: NCA-ECC-2:2024 | C11: Technical (T) | D11: Encryption & Data Protection (T.3) | E11: Technical Configuration | F11: Encryption at rest/transit evidence; certificate management; key rotation logs; data classification matrix; DLP rule evidence | G11: 3 years | H11: → RISK-006: Data exposure → PDPL breach + patient privacy violation
A12: CE-007 | B12: NCA-ECC-2:2024 | C12: Operational (O) | D12: Incident Response (O.1) | E12: IR Plan + Test Records | F12: NCA-aligned IR plan; 24h NCA notification procedure; tabletop exercise report (annual); post-incident review; CSIRT roster | G12: 5 years | H12: → RISK-007: Delayed response → NCA 24h breach → regulatory escalation
A13: CE-008 | B13: NCA-ECC-2:2024 | C13: Operational (O) | D13: BCP & Disaster Recovery (O.2) | E13: BCP + DR Test Evidence | F13: Business impact analysis; RTO/RPO definitions; DR test results (annual); backup verification; failover evidence | G13: 5 years | H13: → RISK-008: Service disruption → patient safety impact → clinical harm
A14: CE-009 | B14: NCA-ECC-2:2024 | C14: Operational (O) | D14: Third-Party Management (O.3) | E14: Vendor Assessment + Contracts | F14: Vendor risk assessments; ECC-2 compliance clauses in contracts; right-to-audit evidence; annual vendor reassessment; NCA-registered CSP verification | G14: Contract + 3yr | H14: → RISK-009: Supply chain compromise → inherited risk → NCA responsibility
A15: CE-010 | B15: PDPL-2021 | C15: Legal/Privacy | D15: Data Subject Rights (PDPL Art. 4-8) | E15: Process Documentation | F15: Consent records; privacy notices; DSAR response logs (30-day SLA); right-to-deletion evidence; data portability procedures | G15: 10 years | H15: → RISK-010: PDPL violation → SDAIA penalty + criminal for breach notification failure
A16: CE-011 | B16: PDPL-2021 | C16: Legal/Privacy | D16: DPIA & Impact Assessment (PDPL Art. 22) | E16: Assessment Report | F16: Data Protection Impact Assessment register; high-risk processing inventory; SDAIA notification for automated decision-making; cross-border transfer assessment | G16: Lifetime + 5yr | H16: → RISK-011: Unassessed processing → unlawful activity → SDAIA enforcement
... A20: CE-015 | B20: CBAHI-HAS-H | C20: Accreditation | D20: Hospital Quality & Safety | E20: Clinical Quality Records | F20: Mortality & morbidity reviews; infection control surveillance; medication error reports; patient satisfaction surveys; clinical audit results | G20: 5 years | H20: → RISK-015: Accreditation loss → cannot bill insurers → operational shutdown
A22: ━━━ SECTION B: EVIDENCE-GAP-TO-RISK MAP — What Happens When Evidence Is Missing ━━━
A23: Risk ID | B23: Evidence Gap | C23: Primary Risk Domain | D23: Secondary Risk | E23: Inherent Risk Level | F23: Regulatory Consequence | G23: Linked KRI | H23: → Lifecycle Phase
A24: RISK-001 | B24: No board-approved cyber strategy / CISO appointment | C24: Governance Failure | D24: Regulatory Risk | E24: 🔴 CRITICAL | F24: NCA-REG-2024: SAR 25M fine + criminal referral for senior management; ECC-2 self-assessment score <60% triggers NCA audit | G24: KRI-X001 | H24: → PLAN phase
A25: RISK-002 | B25: Non-Saudi in mandatory cyber roles / no Saudi ID proof | C25: Workforce Compliance | D25: Regulatory Risk | E25: 🔴 CRITICAL | F25: Dual penalty: NCA ECC-2 non-compliance + MHRSD Nitaqat Red zone; visa block; work permit suspension | G25: KRI-X004 | H25: → OPERATE phase
A26: RISK-003 | B26: No training completion records / phishing test results | C26: Human Factor Vulnerability | D26: Cyber Risk | E26: 🟠 HIGH | F26: NCA finding in self-assessment Domain 1; increased breach probability; insurance may void coverage | G26: KRI-X001 | H26: → OPERATE phase
A27: RISK-004 | B27: No MFA evidence / missing privileged access reviews | C27: Unauthorised Access | D27: Privacy Risk | E27: 🔴 CRITICAL | F27: ECC-2 Domain 2 failure; PDPL breach if patient data accessed; dual NCA+SDAIA enforcement | G27: KRI-X002 | H27: → IMPLEMENT phase
A28: RISK-005 | B28: No segmentation diagram / missing pen test report | C28: Network Compromise | D28: Operational Risk | E28: 🔴 CRITICAL | F28: NCA ECC-2 Domain 2 failure; CNI entities face additional OTCC non-compliance; healthcare facility shutdown possible | G28: KRI-X002 | H28: → IMPLEMENT phase
A29: RISK-006 | B29: No encryption at rest/transit evidence / missing key rotation | C29: Data Exposure | D29: Privacy Risk | E29: 🔴 CRITICAL | F29: ECC-2 + PDPL dual breach; patient data exposed = automatic SDAIA notification; NCA escalation for CNI | G29: KRI-X003 | H29: → IMPLEMENT phase
A30: RISK-007 | B30: No IR plan / missing NCA 24h notification procedure | C30: Delayed Incident Response | D30: Clinical Safety Risk | E30: 🔴 CRITICAL | F30: NCA-REG-2024: failure to report = criminal offence; PDPL 72h breach notification = criminal penalty for DPO | G30: KRI-X001 | H30: → OPERATE phase
A31: RISK-008 | B31: No BIA / untested BCP / no DR evidence | C31: Service Disruption | D31: Patient Safety | E31: 🟠 HIGH | F31: Healthcare system unavailability = clinical harm; CBAHI accreditation jeopardised; MOH escalation | G31: KRI-X001 | H31: → REVIEW phase
A32: RISK-009 | B32: No vendor risk assessment / missing ECC-2 contract clauses | C32: Supply Chain Compromise | D32: Regulatory Risk | E32: 🟠 HIGH | F32: ECC-2 Domain 4 non-compliance; entity retains liability for vendor breach; cloud CSP must be NCA-registered | G32: KRI-X001 | H32: → IMPLEMENT phase
A33: RISK-010 | B33: No consent records / missing DSAR response logs | C33: PDPL Non-compliance | D33: Reputational Risk | E33: 🔴 CRITICAL | F33: SDAIA penalty; data subject compensation claims; criminal referral for DPO if breach unreported | G33: KRI-X003 | H33: → OPERATE phase
A34: RISK-011 | B34: No DPIA register / unassessed high-risk processing | C34: Unlawful Data Processing | D34: Regulatory Risk | E34: 🟠 HIGH | F34: PDPL Art. 22 breach; SDAIA enforcement; cross-border transfer invalid without assessment | G34: KRI-X003 | H34: → PLAN phase
... A38: RISK-015 | B38: Failed CBAHI survey / expired accreditation | C38: Accreditation Loss | D38: Financial Risk | E38: 🟠 HIGH | F38: Cannot bill CCHI-regulated insurers; MOH may restrict patient intake; reputational damage for hospital | G38: N/A | H38: → REVIEW phase
A40: ━━━ SECTION C: RISK-TO-LIFECYCLE MAPPING — When Each Risk Peaks in the GRC Lifecycle ━━━
A41: Lifecycle Phase | B41: Phase Description | C41: Risks Active in This Phase | D41: Key GRC Activities | E41: KSA Frameworks Governing | F41: Evidence Generated | G41: → Policy Required
A42: 1️⃣ PLAN | B42: Strategic planning, risk identification, framework scoping, DPIA, architecture design, vendor selection | C42: RISK-001 (Governance failure); RISK-011 (Unassessed processing); RISK-013 (Unregistered device) | D42: Risk assessment; regulatory landscape scan; DPIA; control selection; architecture review; vendor due diligence; SFDA pre-submission | E42: ECC-2 Domain 1 (Governance); PDPL Art. 22 (DPIA); SFDA MDR (Pre-market); NCA-CCC (Cloud assessment) | F42: Risk register; DPIA report; architecture design; vendor shortlist; SFDA pre-submission dossier; project charter | G42: → POL-001 to POL-004
A43: 2️⃣ IMPLEMENT | B43: Control deployment, system configuration, network segmentation, encryption, OT inventory, NABIDH integration | C43: RISK-004 (Access); RISK-005 (Network); RISK-006 (Data exposure); RISK-009 (Vendor); RISK-012 (OT); RISK-014 (Interop) | D43: IAM deployment; MFA rollout; network segmentation; encryption config; OT zone/conduit; vendor onboarding; NABIDH connectivity | E43: ECC-2 Domains 2-3 (Technical/Operational); OTCC (OT segmentation); NCA-DCC (Data controls); MOH-HIS (Interop) | F43: Configuration evidence; test results; vendor contracts; NABIDH certificate; segmentation diagrams; encryption proof | G43: → POL-005 to POL-009
A44: 3️⃣ OPERATE | B44: Day-to-day operations, monitoring, incident response, training, DSAR handling, Saudisation maintenance | C44: RISK-002 (Saudisation); RISK-003 (Human factor); RISK-007 (IR delay); RISK-010 (PDPL consent) | D44: Continuous monitoring; awareness training; phishing simulation; IR activation; DSAR processing; Nitaqat tracking; KRI monitoring | E44: ECC-2 all domains (continuous); PDPL (consent/DSARs); MHRSD-NITAQAT (workforce); NCA-REG-2024 (reporting) | F44: Training records; monitoring dashboards; IR reports; DSAR logs; Qiwa reports; KRI measurements; NCA notification evidence | G44: → POL-010 to POL-014
A45: 4️⃣ REVIEW | B45: Annual audit, self-assessment, BCP test, accreditation survey, maturity assessment, gap analysis | C45: RISK-008 (BCP untested); RISK-015 (Accreditation loss); all risks resurface for gap identification | D45: NCA self-assessment; PDPL annual audit; BCP/DR test; CBAHI survey; vendor reassessment; maturity assessment; KRI trend analysis | E45: ECC-2 (annual self-assessment); CBAHI-HAS-H (3-year survey); PDPL-IR (annual audit); ZATCA (e-invoice audit) | F45: Self-assessment report; audit findings; BCP test results; CBAHI survey report; gap analysis; improvement plan | G45: → POL-015 to POL-017
A46: 5️⃣ RETIRE / TRANSITION | B46: System decommission, data retention/destruction, vendor exit, framework version migration, legacy device phase-out | C46: RISK-006 (Data exposure during destruction); RISK-013 (Legacy device risk); RISK-009 (Vendor exit risk) | D46: Data sanitisation; certificate revocation; vendor exit management; legacy control migration; PDPL data destruction evidence | E46: PDPL (data retention/destruction); SFDA-MDR (device decommission); NCA-DCC (data lifecycle); ECC-2 (asset disposal) | F46: Data destruction certificates; asset disposal records; vendor exit checklist; migration completion evidence; SFDA deregistration | G46: → POL-018 to POL-020
A48: ━━━ SECTION D: LIFECYCLE-TO-POLICY CHAIN — Required Policies per Phase ━━━
A49: Policy ID | B49: Policy Name | C49: Lifecycle Phase | D49: Regulatory Source | E49: Policy Hierarchy Level | F49: Approval Authority | G49: Review Cycle | H49: → Treatment if Gap
A50: POL-001 | B50: Cybersecurity Strategy & Governance Policy | C50: PLAN | D50: ECC-2 Domain 1 (Governance); NCA-REG-2024 | E50: L1 — Strategic | F50: Board of Directors | G50: Annual | H50: → TRT-001
...

Sheet Content Eval & Shahin-AI
A1: 🧪 CONTENT EVALUATION & SHAHIN-AI OPTIMISATION REPORT
A2: Combined assessment: Human GRC value + AI ingestion readiness + 10-year extensibility architecture
A4: ━━━ PART A: CURRENT CONTENT EVALUATION ━━━
A5: Overall Score: | B5: 8.2 / 10 — EXCEPTIONAL FOUNDATION
A7: Dimension | B7: Score | C7: Assessment | D7: Evidence | E7: Gap / Improvement Needed
A8: 1. Regulatory Coverage Breadth | B8: 46305 | C8: 🏆 WORLD-CLASS — No known GRC database maps this many regulators in a single country | D8: 107 regulators, 405 framework entries, 17 sector groups, 53 data dimensions per framework | E8: None — this exceeds commercial GRC platforms (Archer, ServiceNow, MetricStream)
A9: 2. Data Depth (Core Frameworks) | B9: 9.5/10 | C9: 🏆 EXCEPTIONAL — Top ~30% of rows (NCA, SFDA, PDPL, MOH, SAMA, CBAHI) have fully bespoke content across all 53 columns | D9: ECC-2 row: specific 18 IoMT controls listed, SAR 25M penalty with legal basis, 7 academic citations, specific NIST CSF 2.0 mapping, specific ECC-1→ECC-2 change analysis, Saudisation mandate details | E9: Minor: Some deep rows could add quantitative compliance cost estimates (FTE effort, budget)
A10: 3. Data Depth (Template Rows) | B10: 5.5/10 | C10: ⚠️ SIGNIFICANT GAP — ~70% of rows (ministries, complier entries) use IDENTICAL generic placeholder text in cols AH-BA (22 columns) | D10: Row 181 (MOMAH-ECC2) col AH: 'Institutional theory and regulatory governance theory underpin all KSA...' — same text in 280+ rows. Cols AJ-BA all template text: 'See official source', 'Known criticisms include: implementation gap...' | E10: 🔴 CRITICAL for Shahin-AI: These 280+ identical text blocks will POISON vector embeddings — the AI cannot distinguish MOMAH-ECC2 from MOIA-ECC2 from MKHC-OTCC because 22 of 53 columns are identical. Must either: (a) differentiate content per entity, or (b) mark as 'TEMPLATE' for AI filtering
A11: 4. Bilingual Coverage | B11: 46183 | C11: ⚠️ PARTIAL — Framework titles have Arabic (col G), but ALL analytical text (cols AH-BA) is English-only | D11: Col G has ضوابط الأمن السيبراني الأساسية but cols AH-BA have no Arabic equivalent for penalties, debates, criticisms, governance obligations, KRIs | E11: 🔴 CRITICAL for Shahin-AI: Arabic user queries will force real-time translation of complex regulatory nuance → latency + hallucination risk. Need parallel Arabic columns for: Penalties, Audit Type, IoMT Controls, KRIs, Business Impact
A12: 5. Structural Consistency | B12: 46244 | C12: ✅ STRONG — Consistent 53-column schema; consistent Group numbering (1-17); consistent HC IoT Relevance taxonomy (HIGHEST/HIGH/MODERATE/LOW) | D12: Blank separator rows between groups (expected); consistent regulator codes; consistent framework code format (CODE-VERSION:YEAR) | E12: Minor: Separator rows add noise for AI parsing; some framework codes inconsistent (NCA-ECC-2:2024 vs ECC-2:2024 vs NCA-ECC-2). Need canonical ID
A13: 6. Academic Rigour | B13: 46275 | C13: 🏆 EXCEPTIONAL for core rows — Peer-reviewed citations, specific author+year, balanced FOR/AGAINST academic debate | D13: ECC-2 row: Almohammad & Wills (2021), Al-Khater et al. (2020), Coventry & Branley (2018), Jalali & Kaiser (2018), Bird & Bird (2025), Clyde & Co (2025) | E13: Template rows cite same 5 refs for all 280+ entries — this is detectable by any academic reviewer. Each regulator group should have sector-specific citations
A14: 7. Cross-Sheet Linkage | B14: 46213 | C14: ✅ GOOD — Per-Regulator Summary links to main sheet; HC IoT Ranked is a filtered view; KRI/Maturity/Audit sheets are independent | D14: GRC Intelligence Engine formulas pull from main sheet (verified: 405 frameworks, 107 regulators, 28,239 controls) | E14: KRI Dashboard, Audit Universe, and GRC Maturity are NOT formula-linked to main sheet — they're standalone. Should have COUNTIFS/SUMIFS validating against main data
A15: 8. AI/RAG Readiness | B15: 46152 | C15: 🔴 MAJOR GAP — Data is optimised for human spreadsheet browsing, NOT for AI vectorisation/retrieval | D15: Flat table structure; semicolon-delimited multi-values in single cells; no entity IDs; no chunk boundaries; no metadata tags; no version hashes | E15: 🔴 CRITICAL: Semicolon-separated values (col E: 'ECC-2:2024; OTCC-1:2022; CCC-1:2020') treated as single string by vectoriser. Need relational decomposition. Large text blocks in Debates/Criticisms dilute vector embeddings
A16: 9. Extensibility Architecture | B16: 7.5/10 | C16: ✅ GOOD — New frameworks can be added as rows; new regulators follow established pattern; Regulatory Change Log tracks versions | D16: Consistent schema allows row insertion; Framework Dependencies captures relationships; Change Log has dropdown validation | E16: Need: (a) Framework versioning system with supersession tracking; (b) Schema version control; (c) Deprecation flags; (d) API-ready canonical IDs
A17: 10. KSA Market Leadership Positioning | B17: 9.5/10 | C17: 🏆 UNMATCHED — No competing KSA GRC product maps 107 regulators across 53 dimensions with academic positioning | D17: Global GRC Benchmark confirms: KSA cybersecurity framework stack is deepest globally; 452 framework entries is unprecedented | E17: To maintain 10-year lead: must add quarterly regulatory update cadence; build enforcement case law database; add compliance cost modelling
A19: WEIGHTED AVERAGE | B19: =(10+9.5+5.5+6+8+9+7+5+7.5+9.5)/10 | C19: EXCEPTIONAL FOUNDATION with 3 critical gaps: Template Content Depth (5.5), AI/RAG Readiness (5.0), Bilingual Coverage (6.0)
A22: ━━━ PART B: SHAHIN-AI OPTIMISATION ARCHITECTURE ━━━
A23: How to transform this workbook from a human-browseable spreadsheet into an AI-native knowledge base that powers Shahin-AI's GRC intelligence
A25: 🔴 PROBLEM 1: TEMPLATE TEXT POISONING (Priority: CRITICAL)
A26: Issue: | B26: 280+ rows share IDENTICAL text in 22 columns (AH-BA). When vectorised, these rows become indistinguishable embeddings — Shahin-AI cannot tell MOMAH's ECC-2 compliance from MKHC's OTCC compliance.
A27: Root Cause: | B27: Template text was necessary to fill 405 rows × 53 columns at scale. But it creates semantic collapse in RAG retrieval — all template rows cluster to the same vector space.
A28: Solution A: | B28: Add CONTENT_DEPTH_TIER column to main sheet: 'DEEP' (fully bespoke content) vs 'TEMPLATE' (generic placeholder). Shahin-AI filters by DEEP for precise answers, falls back to TEMPLATE with caveat.
A29: Solution B: | B29: For template rows, generate ENTITY-SPECIFIC differentiators: replace generic 'Penalties defined by issuing authority' with entity-specific penalty context derived from the regulator group and framework type.
A30: Solution C: | B30: Implement HIERARCHICAL INHERITANCE: Template rows inherit base properties from their Group parent + Framework parent. AI retrieves parent properties and applies entity context. Reduces duplication by 90%.
A32: 🔴 PROBLEM 2: FLAT DELIMITERS (Priority: CRITICAL)
A33: Issue: | B33: Semicolon-separated multi-values in single cells (col E: 'ECC-2:2024; OTCC-1:2022; CCC-1:2020') are treated as a single string by standard vectorisation, not as discrete relational entities.
A34: Solution: | B34: Pre-processing script (TypeScript/Python) to split semicolon-delimited fields into relational entities. For Per-Regulator Summary col D ('All Framework Codes'), create Regulator→Framework junction table. Expose via OpenClaw MCP endpoints.
A36: 🟠 PROBLEM 3: SEMANTIC DILUTION IN LONG TEXT (Priority: HIGH)
A37: Issue: | B37: Large text blocks in 'Academic Debates' (col AJ), 'Key Changes Summary' (col R) contain 5-10 distinct ideas in one cell. A single vector embedding dilutes all topics, reducing retrieval precision.
A38: Solution: | B38: RAG chunking strategy: Break each long text field into semantic chunks with high metadata density. Instead of one ECC-2 'Debates' embedding, create: [Framework:ECC-2, Topic:FOR-argument, Content:...], [Framework:ECC-2, Topic:AGAINST-argument, Content:...], [Framework:ECC-2, Topic:IoMT-gap, Content:...]
A40: 🟠 PROBLEM 4: BILINGUAL GAP (Priority: HIGH)
A41: Issue: | B41: Arabic user queries force real-time LLM translation of English regulatory text. Complex terminology (e.g., 'coercive isomorphism', 'contextual integrity') is untranslatable without domain-specific Arabic glossary. Latency + hallucination risk.
A42: Solution: | B42: Add parallel Arabic columns for top 10 operational fields: Penalty_AR, Audit_Type_AR, IoMT_Controls_AR, KRI_AR, Business_Impact_AR, Governance_Obligations_AR, Risk_Domains_AR, Compliance_Type_AR, Control_Categories_AR, Testing_Methods_AR. Allows direct Arabic retrieval without translation overhead.
A44: 🟡 PROBLEM 5: NO CANONICAL IDs (Priority: MODERATE)
A45: Issue: | B45: Framework codes are inconsistent: 'NCA-ECC-2:2024' vs 'ECC-2:2024' vs 'NCA-ECC-2'. No UUID/hash for version tracking. No entity relationship IDs for Knowledge Graph construction.
A46: Solution: | B46: Add columns: CANONICAL_ID (e.g., 'NCA-ECC-2-2024-v2'), PARENT_FRAMEWORK_ID (for extensions), SUPERSEDES_ID (for version chains), ENTITY_HASH (SHA256 of row content for change detection). Expose via MCP server getFrameworkById() endpoint.
A49: ━━━ PART C: SHAHIN-AI INGESTION ARCHITECTURE ━━━
A50: How to expose this knowledge base through Shahin-AI's stack: OpenClaw MCP Server + RAG Pipeline + Frontend NOC
A52: Layer | B52: Component | C52: Purpose | D52: Implementation | E52: Priority
A53: 💾 1. DATA LAYER | B53: CSV → JSONL Converter | C53: Transform flat CSV rows into nested JSON documents with proper typing, arrays, and relationships | D53: TypeScript script: parse each row → split semicolons → create {regulator: {code, name, group}, frameworks: [{code, name, relevance, controls}], metadata: {...}}. Output: one .jsonl per regulator. | E53: 🔴 P1
...

Sheet All 108 Regulators - Frameworks
A1: # | B1: Regulator Code | C1: Regulator Name | D1: Group | E1: Framework Code | F1: Framework Name (EN) | G1: Framework Name (AR) | H1: Current Version | I1: Year First Issued | J1: Controls | K1: Framework Type | L1: Role | M1: Who Must Comply / Scope | N1: HC IoT Relevance | O1: Official Source URL | P1: Source Name | Q1: Version History (All Versions) | R1: Key Changes Per Version | S1: Enforcement / Effective Date | T1: Next Review / Expected Update | U1: Current Status | V1: Penalty / Non-Compliance Consequence | W1: Enforcing Authority | X1: Healthcare Sub-Sector Applicability | Y1: Public / Private Sector Scope | Z1: Audit Type | AA1: Audit Frequency | AB1: IoMT-Specific Controls Count / Details | AC1: International Standard Alignment | AD1: Document Language | AE1: GH-ICGA Framework Layer Mapping | AF1: Maturity Model Available | AG1: Vision 2030 Programme Link | AH1: Evidence Required for Compliance | AI1: Theoretical Grounding / Academic Basis | AJ1: Academic Debates (For vs Against) | AK1: Known Criticisms & Gaps | AL1: Comparative Positioning vs Alternatives | AM1: Key Foundational Citations (Harvard) | AN1: How to Learn / Training Resources | AO1: GH-ICGA Thesis Positioning | AP1: GRC Pillar (G/R/C) | AQ1: Governance Obligations | AR1: Risk Domains Covered | AS1: Compliance Obligation Type | AT1: Control Categories (A/T/P/O) | AU1: Key Risk Indicators (KRIs) | AV1: Control Testing Methods | AW1: GRC Tool Support | AX1: Third-Party / Supply Chain GRC | AY1: Business Impact of Non-Compliance | AZ1: Applicable Sectors (All 17 Groups) | BA1: Cross-Sector Framework?
B3: ── 3. Cybersecurity & Data ── | BB3: CONTENT_DEPTH_TIER | BC3: AI_CHUNK_ID | BD3: CANONICAL_FRAMEWORK_ID | BE3: PARENT_FRAMEWORK_ID | BF3: SHAHIN_PRIORITY_SCORE
A4: 1 | B4: NCA | C4: National Cybersecurity Authority | D4: 3. Cybersecurity & Data | E4: ECC-2:2024 | F4: Essential Cybersecurity Controls | G4: ضوابط الأمن السيبراني الأساسية | H4: ECC-2:2024 (Oct 2024) | I4: 2018 | J4: 108 | K4: ISSUES/ENFORCES | L4: Mandatory Enforcer | M4: All gov. entities + CNI operators incl. hospitals | N4: HIGHEST | O4: https://nca.gov.sa/en/regulatory-documents/controls-list/ecc/ | P4: NCA official; Clyde & Co Jan 2025; Wattlecorp Nov 2025 | Q4: ECC-1:2018 → ECC-2:2024 | R4: v1 (2018): 114 controls, 5 domains. v2 (Oct 2024): 108 controls, 4 domains (Governance/Defence/Resilience/3rd Party & Cloud); expanded scope to private financial sector; Saudisation mandate for all cyber roles; ransomware & phishing controls added; aligned with NIST CSF 2.0 & ISO 27001:2022 | S4: ECC-1: Jan 2019 (compliance). ECC-2: Oct 2024 (issued); 12-month transition window ends Oct 2025 | T4: Ongoing — NCA reviews after major incidents or every 3-4 years | U4: CURRENT — ECC-2:2024 is the mandatory version as of Oct 2025 | V4: SAR 25M max fine (NCA-REG-2024); licence revocation; criminal referral; business suspension; public naming in NCA disclosure | W4: NCA — dedicated inspectors with judicial powers (Dec 2024 regulation); NCA Supervisory Affairs Dept | X4: Hospital; Clinic; Lab; Medical Device Manufacturer; Health IT Vendor; Health Insurer; Pharmacy; Government Health Entity | Y4: Both (gov. + private CNI operators) | Z4: Annual self-assessment + NCA external audit (surprise or scheduled); third-party assessment for critical entities | AA4: Annual self-assessment; NCA external: every 2-3 years or triggered by incident | AB4: 18 (device inventory 1-2-1; IoT/OT segmentation 2-4-x; device patch management 2-2-x; remote access 2-8-x; monitoring 2-11-x; third-party device governance 2-15-x) | AC4: NIST CSF 2.0 (explicit mapping); ISO 27001:2022 (explicit mapping); IEC 62443 (partial); CIS Controls v8 | AD4: Arabic + English (official bilingual) | AE4: Layer 1: Governance; Layer 2: Risk Management; Layer 3: Technical Controls; Layer 4: Compliance; Layer 5: Assurance | AF4: Yes — 5 maturity levels (Initial / Developing / Defined / Managed / Optimising); annual self-scoring required | AG4: Vision 2030 Digital Transformation; National Cybersecurity Strategy 2020-2030; HSTP digital health targets | AH4: Asset inventory; risk register; policy documentation; access control logs; patch records; incident response plan; annual self-assessment report; staff awareness training records | AI4: Governance theory (Bevir 2012): centralised regulatory authority. Risk management theory (ISO 31000): risk-based control selection. Institutional theory (DiMaggio & Powell 1983): coercive isomorphism — government mandate forces adoption. | AJ4: FOR: Nationally contextualised; stronger than NIST CSF for enforcement; Arabic-first design reduces adoption friction in KSA; mandatory Saudisation closes workforce gap. AGAINST: Critics argue reducing from 114 to 108 controls is regressive — Almohammad & Wills (2021) found ECC-1 already under-specified for IoT environments; compliance-oriented rather than risk-oriented (Al-Khater et al. 2020); no formal IoT-specific annex despite ECC-2 expansion | AK4: No dedicated IoMT/medical device sub-framework; Saudisation mandate may worsen near-term skills shortage before improving it (Clyde & Co 2025); maturity model self-assessment lacks independent verification; gap between ECC compliance and actual security posture documented by Almohammad & Wills (2021); ECC-1 to ECC-2 transition period too short for healthcare entities (12 months) | AL4: ECC-2 vs NIST CSF 2.0: ECC-2 is MANDATORY, CSF voluntary; ECC-2 KSA-specific, CSF global. ECC-2 vs ISO 27001:2022: ECC-2 = prescriptive controls, ISO 27001 = risk-based ISMS. ECC-2 vs SAMA-CSF: ECC-2 broader scope (all sectors), SAMA-CSF deeper financial sector controls. ECC-2 scores HIGHEST on enforceability; LOWEST on IoMT specificity vs IEC 62443 | AM4: Almohammad A & Wills G (2021) 'Cybersecurity Challenges in Saudi Arabia' J Cybersecurity 7(1); Al-Khater WA et al. (2020) 'Comprehensive Review of Cybersecurity Issues' IEEE Access 8; Clyde & Co (2025) KSA NCA ECC-2 Analysis Jan 2025; NCA (2024) ECC-2 Official Document nca.gov.sa; Bird & Bird (2025) Saudi Arabia Cybersecurity Authority Regulations Jan 2025 | AN4: Official: NCA website (nca.gov.sa) — free downloads. Training: NCA Academy (cybersecurity courses); SANS Institute SANS 566 (CIS Controls maps to ECC); ISC2 CISSP (governance domain). Certification: NCA-recognised cybersecurity certifications. Language: Arabic + English. Estimated study time: 40 hours for full ECC-2 mastery | AO4: PRIMARY driver for GH-ICGA Layer 1 (Governance) and Layer 4 (Compliance). ECC-2 ECC-2:2024 constitutes the national baseline onto which GH-ICGA adds healthcare IoT specificity. Thesis position: GH-ICGA extends ECC-2 with IoMT-specific controls that ECC-2 currently lacks — justified by 18 IoMT-relevant controls in ECC-2 vs 53+ needed for full IoMT governance per preliminary GH-ICGA framework | AP4: G + R + C (all three — primary cross-pillar framework) | AQ4: Board: approve cybersecurity strategy + ECC self-assessment annually. CISO: own ECC compliance programme; report to board quarterly. IT/OT Ops: implement controls; maintain evidence. All cybersecurity roles: Saudi nationals (ECC-2 mandate). CISO must hold NCA-recognised certification | AR4: Cyber Risk (PRIMARY); Operational Risk; Strategic Risk (Saudisation); Supply Chain Risk (third-party domain); Reputational Risk (NCA public naming on breach) | AS4: LEGAL — Mandatory under Saudi Cybersecurity Law (Royal Decree M/33 2020) + NCA-REG-2024 enforcement regulation. Criminal and administrative sanctions apply | AT4: Administrative (A): 38 controls — policies, governance, training, awareness. Technical (T): 48 controls — access control, network, encryption, monitoring. Operational (O): 22 controls — incident response, BCP, vendor management | AU4: 1. ECC self-assessment score (target ≥3.5/5 per domain). 2. % open ECC findings from last audit. 3. Time-to-patch critical vulnerabilities (target <30 days). 4. % Saudi nationals in cybersecurity roles (target 100%). 5. # cyber incidents reported to NCA within 24h. 6. Third-party compliance rate | AV4: Annual self-assessment (NCA template); NCA external audit (interview + evidence review + technical testing); Penetration test (annual for CNI entities); Configuration review; Access control audit; Social engineering simulation | AW4: IBM OpenPages; ServiceNow GRC; MetricStream; RSA Archer; Nuvolo (OT); NCA self-assessment portal (custom). KSA-specific: NCA compliance tracking platform (government entities). OneTrust for policy management | AX4: ECC-2 Domain 4 (Third-Party & Cloud): mandatory third-party risk assessment before engagement; annual third-party reassessment; contractual ECC compliance obligation in vendor contracts; cloud providers must be NCA-registered; OTCC applies to OT vendors with remote access | AY4: Non-compliance: SAR 25M fine (max); licence suspension; business closure; public naming; criminal referral. Operational impact: NCA can order shutdown of non-compliant systems. Reputational: public disclosure damages patient and investor trust. Competitive: non-compliant health IT vendors excluded from MOH/NUPCO tenders | AZ4: Sector-specific — consult official source | BA4: Sector-Specific | BB4: =IF(E4="","",IF(ISNUMBER(SEARCH("Institutional theory and regulatory governance theory underpin",AI4)),"TEMPLATE",IF(LEN(AI4)>100,"DEEP",IF(AI4="","SPARSE","SHALLOW")))) | BC4: =IF(E4="","",D4&"-"&B4&"-"&E4) | BD4: =IF(E4="","",SUBSTITUTE(SUBSTITUTE(B4&"-"&E4," ",""),":","-")) | BE4: =IF(E4="","",IF(ISNUMBER(SEARCH("ECC",E4)),"NCA-ECC-2-2024",IF(ISNUMBER(SEARCH("OTCC",E4)),"NCA-ECC-2-2024",IF(ISNUMBER(SEARCH("CCC",E4)),"NCA-ECC-2-2024",IF(ISNUMBER(SEARCH("DCC",E4)),"NCA-ECC-2-2024",IF(ISNUMBER(SEARCH("CSCC",E4)),"NCA-ECC-2-2024",IF(ISNUMBER(SEARCH("PDPL-IR",E4)),"PDPL-2021",IF(ISNUMBER(SEARCH("PDPL-DTR",E4)),"PDPL-2021","NONE")))))))) | BF4: =IF(E4="","",IF(BB4="DEEP",10,IF(BB4="SHALLOW",5,IF(BB4="TEMPLATE",3,1)))+IF(N4="HIGHEST",5,IF(N4="HIGH",3,IF(N4="MODERATE",1,0)))+IF(ISNUMBER(SEARCH("Mandatory",L4)),3,0))
A5: 2 | B5: NCA | C5: National Cybersecurity Authority | D5: 3. Cybersecurity & Data | E5: OTCC-1:2022 | F5: OT Cybersecurity Controls | G5: ضوابط الأمن السيبراني للتقنيات التشغيلية | H5: OTCC-1:2022 | I5: 2022 | J5: 53 | K5: ISSUES/ENFORCES | L5: Mandatory Enforcer | M5: OT/ICS/SCADA incl. medical device networks | N5: HIGHEST | O5: https://nca.gov.sa/otcc_en.pdf | P5: NCA OTCC PDF; Resecurity | Q5: OTCC-1:2022 (First issue) | R5: First dedicated OT/ICS cybersecurity standard for KSA. 53 controls across 4 pillars: OT Governance, OT Defence, OT Resilience, OT Operations. Extends ECC-1:2018 with ICS/SCADA-specific requirements. References IEC 62443 series and NIST SP 800-82. Covers medical device OT networks in hospitals as CNI | S5: Issued: 2022. Compliance mandatory for CNI OT operators | T5: Review expected when ECC-3 released or after 5 years | U5: CURRENT — first and only version | V5: SAR 25M max (NCA-REG-2024 applies); operational shutdown of non-compliant OT systems; CNI operator licence at risk | W5: NCA — OT/ICS specialist inspectors; coordinates with sector regulators (MOH, ECRA, KACARE) for CNI OT audits | X5: Hospital (medical device OT networks); Medical Device Manufacturer; Pharmacy (automated dispensing); Lab (automated systems); Health IT Vendor (OT integration) | Y5: Both (all CNI operators — hospitals qualify as CNI) | Z5: NCA OT assessment; sector-specific OT audit; ICS security assessment by accredited third party | AA5: Biennial NCA assessment; annual internal OT security review | AB5: 53 of 53 — entire framework is OT/ICS applicable; directly covers medical device networks (2-4-x network segmentation; 2-6-x remote access; 2-9-x patch management for OT) | AC5: IEC 62443 (explicit reference); NIST SP 800-82 Rev 3; ISA/IEC 62443-2-1; ISO 27001:2022 (partial) | AD5: Arabic + English (official bilingual) | AE5: Layer 3: Technical Controls (primary); Layer 2: Risk Management; Layer 4: Compliance | AF5: Yes — aligned with IEC 62443 Security Levels (SL1-SL4); OTCC maps to SL2 minimum for healthcare CNI | AG5: National Cybersecurity Strategy; Vision 2030 Healthcare Digital Transformation; HSTP connected medical device targets | AH5: OT asset inventory; network segmentation diagrams; OT patch logs; remote access logs; OT incident response plan; ICS risk assessment report; vendor access audit logs | AI5: Socio-technical systems theory (Trist 1981): OT/IT convergence requires integrated governance. Defence-in-depth (NIST): layered security for critical systems. Critical infrastructure protection theory: availability > confidentiality in OT environments. | AJ5: FOR: First KSA standard addressing ICS/SCADA — fills critical gap identified in Nurse et al. (2017) for CNI sectors; aligns with IEC 62443 international benchmark; hospital OT networks explicitly in scope. AGAINST: Medical IoT falls between OTCC (OT-centric) and ECC-2 (IT-centric) — Coventry & Branley (2018) argue medical devices need dedicated classification not forced into OT/IT binary; OTCC written for industrial OT, clinical environment nuances absent | AK5: Clinical IoMT context absent — infusion pumps and ventilators behave differently from SCADA; no clinical engineering expertise incorporated in drafting; 53 controls insufficient for complex hospital OT topology documented by Jalali & Kaiser (2018); conflict between availability-first OT principle and confidentiality-first healthcare requirement unresolved | AL5: OTCC vs IEC 62443: OTCC mandatory in KSA; IEC 62443 voluntary but globally recognised — OTCC maps to IEC 62443-2-1 security management but lacks 62443-4-2 component-level detail. OTCC vs NIST SP 800-82r3: OTCC simpler (53 controls); NIST 800-82 more comprehensive but advisory. OTCC + SFDA-MDR combined = closest to full IoMT coverage | AM5: Coventry L & Branley D (2018) 'Cybersecurity in Healthcare' BMJ 2018; Jalali MS & Kaiser JP (2018) 'Cybersecurity in Hospitals' JMIR 20(5); Nurse JRC et al. (2017) 'Security Risk Assessment in IoT' IEEE IoT J; NCA (2022) OTCC-1:2022 nca.gov.sa/otcc_en.pdf; ISA/IEC 62443-2-1 (2009) Security Management System for IACS | AN5: Official: OTCC PDF (nca.gov.sa). Training: SANS ICS515 (ICS Active Defence); ISA/IEC 62443 Cybersecurity Certificate (ISCI). Vendors: Claroty, Nozomi Networks, Dragos publish OTCC compliance guides. Estimated: 60 hours (requires ICS/SCADA foundation knowledge first) | AO5: GH-ICGA Layer 3 (Technical Controls) — directly informs IoMT technical control set in preliminary GH-ICGA. Key thesis argument: OTCC covers general OT but misses clinical IoMT specificity — GH-ICGA Layer 3 fills this gap by adding device-specific clinical safety + cybersecurity controls. Referenced in thesis RQ2 on technical governance gaps | AP5: G + C (Governance + Compliance — standard regulatory framework positioning) | AQ5: Senior management: accountability for framework compliance. Designated compliance officer: monitor requirements. All staff: awareness of applicable obligations | AR5: Regulatory Risk; Operational Risk; Reputational Risk — specific domains determined by framework scope | AS5: See official source — legal obligation, regulatory requirement, or voluntary standard as applicable | AT5: Administrative; Technical; Operational — specific distribution determined by framework content | AU5: 1. Compliance status (compliant/non-compliant). 2. # open findings from last assessment. 3. % controls implemented. 4. Time to remediate findings. 5. Incident rate in framework scope area | AV5: Self-assessment; internal audit; external assessment as specified by issuing authority | AW5: ServiceNow GRC; IBM OpenPages; RSA Archer; MetricStream — all major GRC platforms support custom framework import. Contact vendor for framework-specific module | AX5: Third parties in scope must demonstrate equivalent compliance. Contractual compliance obligations; right-to-audit clauses; annual third-party assessment | AY5: Non-compliance: regulatory action by issuing authority; fines and penalties as specified; operational and reputational consequences | AZ5: Sector-specific — consult official source | BA5: Sector-Specific | BB5: =IF(E5="","",IF(ISNUMBER(SEARCH("Institutional theory and regulatory governance theory underpin",AI5)),"TEMPLATE",IF(LEN(AI5)>100,"DEEP",IF(AI5="","SPARSE","SHALLOW")))) | BC5: =IF(E5="","",D5&"-"&B5&"-"&E5) | BD5: =IF(E5="","",SUBSTITUTE(SUBSTITUTE(B5&"-"&E5," ",""),":","-")) | BE5: =IF(E5="","",IF(ISNUMBER(SEARCH("ECC",E5)),"NCA-ECC-2-2024",IF(ISNUMBER(SEARCH("OTCC",E5)),"NCA-ECC-2-2024",IF(ISNUMBER(SEARCH("CCC",E5)),"NCA-ECC-2-2024",IF(ISNUMBER(SEARCH("DCC",E5)),"NCA-ECC-2-2024",IF(ISNUMBER(SEARCH("CSCC",E5)),"NCA-ECC-2-2024",IF(ISNUMBER(SEARCH("PDPL-IR",E5)),"PDPL-2021",IF(ISNUMBER(SEARCH("PDPL-DTR",E5)),"PDPL-2021","NONE")))))))) | BF5: =IF(E5="","",IF(BB5="DEEP",10,IF(BB5="SHALLOW",5,IF(BB5="TEMPLATE",3,1)))+IF(N5="HIGHEST",5,IF(N5="HIGH",3,IF(N5="MODERATE",1,0)))+IF(ISNUMBER(SEARCH("Mandatory",L5)),3,0))
